Workbook

Sheet メモ
A1: 45954 | B1: キックオフ＆共有フォルダルール決め
A2: 45969 | B2: 物理サーバ更新
A3: 45970 | B3: 物理サーバ更新
A4: 45971 | B4: 物理サーバ更新完了
B5: 物理サーバ更新中に、SSC社内で 部署毎・業務毎に
B6: 共有フォルダの運用ルール・管理担当 一次案を決める
A7: 46006 | B7: 進捗確認
B8: ↓共有フォルダ運用体制、MS365、セキュリティ対策 ⇄ IT基本勉強会、MS365勉強会 等 実施予定
A10: 46063 | B10: ①共有フォルダ：整備状況を報告､年月日フォルダの階層軽減効率化にあたって更新日時をファイル名に自動で付与するツールについてご相談。認識レベルによって漏れる可能性もあるが実効性は高いためインフィニティ様で検討いただく。
B11: ②クラウドバックアップ整備：現実的な選択肢についてご相談。「MS365OneDrive」手動にはなるがOffice込みなのでアプリ環境がなくてもデータを開くことができる「専用サービス」アプリ環境にダウンロードしないと開けないが必要なものだけ厳選すれば作業効率･費用面で候補となる。当課題は①③の状況を見ながら追って方向性を決めていく。
B12: ③事務作業自動化(AI化)：本日のメイン課題､具体的な取り組みについてご相談。今は生成AIのみならずAIエージェントも機能性や精度が充実してきており代表的なサービスを説明いただいた。いきなり広範囲･高負荷作業で検討するよりも身近な課題を前向きなメンバーでやりながらテンプレ化して共有する方が定着しやすいとのことで先ず社内ヒアリングで気軽な意見を収集してから具体的な考察に入ることとした。ミーティング終了後参加メンバーでヒアリング項目案を出し今週配布～来週半ばに回収～とりまとめ～次回2/24提出する。
B13: ④Q美レンタルサーバ移設検討報告(迷惑メールフィルター脆弱)
A15: 46073 | B15: 先日実施した業務改善ヒアリング（回答数：27名）の結果を踏まえ、DX推進に関してインフィニティ様へ相談したい内容を整理しましたので共有いたします。今回のヒアリングでは、主に以下の課題が確認されました。
B16: ・Excelへの手入力や転記、集計などの手作業が多い
B17: ・紙帳票での運用が残っており、作成・保管・検索に工数がかかっている
B18: ・定型業務が自動化されておらず、日常業務に時間を要している
B19: ・業務フローが属人化しており、確認や照合作業に時間がかかっている
B20: 上記課題を踏まえ、インフィニティ様へは主に以下の内容を相談予定です。
B21: ① 紙帳票の電子化の進め方：製造記録や各種帳票の電子化にあたり、最適な手法・ツール・導入方法について相談
B22: ② Excel業務の効率化・自動化：集計・転記・資料作成などの定型業務について、自動化の進め方および優先順位の整理
B23: ③ 業務フローの整理およびDX推進の進め方：現状業務の可視化、DX推進の優先順位、段階的な導入ロードマップの策定
B24: ④ AIツールの業務活用に関する導入方針：AIを活用可能な業務領域の整理および、社内での安全な活用環境の構築方法
B25: 今回の相談では、いきなりシステム導入を決定するのではなく、「どの業務からDXを進めるべきか」「どのような進め方が現実的か」といった全体方針を整理することを目的としています。
A27: 46077 | B27: 中土主任にて社内ヒアリング配布-回収-要約していただいた内容に基づいて社内業務効率化の進め方(どの業務から/どうすれば現実的か)､全体方針の整理について打合せ。
B28: インフィニティ様の支援実績では数時間かかるような大きな業務から着手するよりも数分程度の業務で日々多数の人が関わるものから実施した方が定着率が良いとのことで先ずExcel業務の効率化(収集/転記/集計/作成など定型業務)から着手しその状況を見ながら紙帳票の電子化､業務フロー整理､AIツール導入､業務フロー再構築へと進めていく形で検討することとなった。
B29: 今回のヒアリングでは業務内容が多岐に渡り社内で実務を確認するのも時間がかかるため3月はプレDXを中断していただくことし4/14再開を目標として3月中旬に進捗状況を共有することとした。
A31: 46077 | B31: ② Excel業務の効率化・自動化：集計・転記・資料作成などの定型業務について、自動化の進め方および優先順位の整理
B32: ∟初動はここから着手し、小さな範囲で小さな成果を出し、社内に「前向きな空気」を広げていく。
B33: ∟先ず、ヒアリング内容の中で、初動計画で着手したら良さそうな候補を共有したいです。
B34: ∟その後、具体的にどんなツール/業務フローで実行していけそうか、草案を共有したいです。 ▶具体的な日程を相談したいです。
B35: ① 紙帳票の電子化の進め方：製造記録や各種帳票の電子化にあたり、最適な手法・ツール・導入方法について相談
B36: ∟ペーパーレス化/DX推進の本旨に基づいて、②の進捗を圧迫しない範囲で並行して検討を進める。
B37: ∟作成内容/業務フローを鑑みて、ヒアリング内容の中から社内で相談しやすそうな候補を共有したいです。
B38: ∟その後、具体的にどんなツール/業務フローで実行していけそうか、草案を共有したいです。
B39: ③ 業務フローの整理およびDX推進の進め方：現状業務の可視化、DX推進の優先順位、段階的な導入ロードマップの策定
B40: ④ AIツールの業務活用に関する導入方針：AIを活用可能な業務領域の整理および、社内での安全な活用環境の構築方法
B41: AIを活用可能な業務領域の整理および、社内での安全な活用環境の構築方法
B42: ∟②①を実施していく中で社内の実情や温度感も踏まえて考察を深めていき、中盤以降に具体化する。
B43: Ⓐ MS365
... B46: ∟②①Ⓐを踏まえ、インフィニティ様おすすめツールの活用方法、それ以外でも検討したいツールなど、率直な意見を共有したいです。▶具体的な日程を相談したいです。
...

Sheet 全体
A1: 開始 | B1: 完了(目標) | C1: 1区分 | D1: 2区分 | E1: 3区分 | F1: 46204 | G1: データベース： キーワード 課題/提案 意識/姿勢 候補者 埋める
A2: 46106 | B2: 46142 | C2: 1.サーバ環境 | D2: ▶サーバリプレイス後の動作改善確認
A3: 46106 | B3: 46142 | C3: 1.サーバ環境 | D3: ▶サーバリプレイス後の動作改善確認 | E3: ログイン・接続：時間帯、切断、フリーズ、速さ
A4: 46106 | B4: 46142 | C4: 1.サーバ環境 | D4: ▶サーバリプレイス後の動作改善確認 | E4: アプリ動作：Outlook（メール検索、迷惑メール） | G4: リアルタイム共有 | I4: 46126
A5: 46106 | B5: 46142 | C5: 1.サーバ環境 | D5: ▶サーバリプレイス後の動作改善確認 | E5: アプリ動作：Excel、PDF、Word、ブラウザ | G5: ワークフロー | I5: 46136
A6: 46106 | B6: 46142 | C6: 1.サーバ環境 | D6: ▶サーバリプレイス後の動作改善確認 | E6: その他1：デスクトップアイコン位置・既定プリンタの固定 | G6: 案件タスク管理 | I6: 46154
A7: 46106 | B7: 46142 | C7: 1.サーバ環境 | D7: ▶サーバリプレイス後の動作改善確認 | E7: その他2：テプラ | G7: 履歴管理 | I7: 46168
A8: 46106 | B8: 46173 | C8: 1.サーバ環境 | D8: ▶サーバリプレイス後の動作改善確認 | E8: Wi-Fi接続：製造エリア、自動⇄手動 | G8: 自動通知 | I8: 46182
A9: 46106 | B9: 46173 | C9: 1.サーバ環境 | D9: ▶サーバリプレイス後の動作改善確認 | E9: TPiCS・PI-navi：現品票発行、タブレット、ハンディターミナル | G9: 拠点外作業 | I9: 46197
A10: 46106 | B10: 46356 | C10: 2.クラウド環境 | D10: ▶MS365
A11: 46106 | B11: 46142 | C11: 2.クラウド環境 | D11: ▶MS365 | E11: 奉行クラウド主担当･TPiCS主担当・営業担当 アカウント導入
A12: 46204 | B12: 46295 | C12: 2.クラウド環境 | D12: ▶MS365 | E12: 部署別・業務別アカウント 導入
A13: 46266 | B13: 46356 | C13: 2.クラウド環境 | D13: ▶クラウドバックアップ整備
A14: 46266 | B14: 46326 | C14: 2.クラウド環境 | D14: ▶クラウドバックアップ整備 | E14: 部署別OneDrive
A15: 46266 | B15: 46326 | C15: 2.クラウド環境 | D15: ▶クラウドバックアップ整備 | E15: 専用サービス導入 有無判断➡一次整備完了
A16: 46106 | B16: 46203 | C16: 3.業務データ | D16: ▶共有フォルダ整備
A17: 46113 | B17: 46142 | C17: 3.業務データ | D17: ▶共有フォルダ整備 | E17: 共有フォルダ：可視化ツール➡削除範囲特定
A18: 46127 | B18: 46173 | C18: 3.業務データ | D18: ▶共有フォルダ整備 | E18: 共有フォルダ：コピー移行ツール➡バックアップ・削除
A19: 46113 | B19: 46203 | C19: 3.業務データ | D19: ▶共有フォルダ整備 | E19: 共有フォルダ：検索ツール➡使用頻度順位付け
A20: 46204 | B20: 46254 | C20: 3.業務データ | D20: ▶共有フォルダ整備 | E20: 共有フォルダ：データリンク集➡Excelハイパーリンク
A21: 46204 | B21: 46265 | C21: 3.業務データ | D21: ▶共有フォルダ整備 | E21: 共有フォルダ：定期メンテナンス方法確定
A22: 46106 | B22: 46326 | C22: 3.業務データ | D22: ▶事務作業自動化(AI化)
A23: 46106 | B23: 46173 | C23: 3.業務データ | D23: ▶事務作業自動化(AI化) | E23: 議事録
A24: 46106 | B24: 46173 | C24: 3.業務データ | D24: ▶事務作業自動化(AI化) | E24: Excel-製造関連
A25: 46174 | B25: 46234 | C25: 3.業務データ | D25: ▶事務作業自動化(AI化) | E25: 日報 改善
A26: 46174 | B26: 46356 | C26: 3.業務データ | D26: ▶データ形式標準化
A27: 46174 | B27: 46356 | C27: 3.業務データ | D27: ▶データ形式標準化 | E27: (▶事務作業自動化(AI化)、▶共有フォルダ整備 進捗に応じて検討開始）
A28: 46143 | B28: 46356 | C28: 3.業務データ | D28: ▶PDM・PLM環境整備
A29: 46143 | B29: 46356 | C29: 3.業務データ | D29: ▶PDM・PLM環境整備 | E29: サービス調査～開発・品管ヒアリング～具体化～
A30: 46174 | B30: 46326 | C30: 3.業務データ | D30: ▶ペーパーレス化・データ化
A31: 46174 | B31: 46326 | C31: 3.業務データ | D31: ▶ペーパーレス化・データ化 | E31: (▶事務作業自動化(AI化)、▶共有フォルダ整備 進捗に応じて検討開始）
A32: 46143 | B32: 46326 | C32: 4.ナレッジ共有 | D32: ▶ナレッジ共有（平準化）
A33: 46113 | B33: 46326 | C33: 4.ナレッジ | D33: ▶ナレッジ共有（平準化） | E33: マニュアル作成（属人化回避）
A34: 46235 | B34: 46326 | C34: 4.ナレッジ | D34: ▶ナレッジ共有（平準化） | E34: 日報 活用
A35: 46143 | B35: 46203 | C35: 5.リテラシー向上 | D35: ▶セキュリティ対策・IT基礎知識勉強会
A36: =B36-7*3 -> 46133 | B36: 46154 | C36: 5.リテラシー向上 | D36: ▶セキュリティ対策・IT基礎知識勉強会 | E36: セキュリティ対策・IT基礎知識勉強会①【？？？】
A37: =B37-7*3 -> 46147 | B37: 46168 | C37: 5.リテラシー向上 | D37: ▶セキュリティ対策・IT基礎知識勉強会 | E37: セキュリティ対策・IT基礎知識勉強会②【？？？】
A38: =B38-7*3 -> 46161 | B38: 46182 | C38: 5.リテラシー向上 | D38: ▶セキュリティ対策・IT基礎知識勉強会 | E38: セキュリティ対策・IT基礎知識勉強会③【？？？】
A39: 46054 | B39: 46387 | C39: - | D39: -

Sheet 予定P
J1: 全選択→更新→「-」「(空白)」非表示 | K1: 全選択→更新→「(空白)」非表示
A2: 年 (開始) | B2: 月 (開始) | C2: 個数 / 3区分 | D2: 個数 / 2区分 | E2: 個数 / 1区分 | G2: 年 (開始) | H2: 月 (開始) | I2: 1区分 | J2: 2区分 | K2: 3区分 | L2: 年 (完了(目標)) | M2: 月 (完了(目標))
A3: <2026/2/1 | B3: <2026/2/1 | G3: 2026年 | H3: 3月 | I3: 1.サーバ環境 | J3: ▶サーバリプレイス後の動作改善確認 | K3: ログイン・接続：時間帯、切断、フリーズ、速さ | L3: 2026年 | M3: 4月
A4: 2026年 | B4: 2月 | D4: 1 | E4: 1 | K4: アプリ動作：Outlook（メール検索、迷惑メール） | L4: 2026年 | M4: 4月
B5: 3月 | C5: 10 | D5: 14 | E5: 14 | K5: アプリ動作：Excel、PDF、Word、ブラウザ | L5: 2026年 | M5: 4月
B6: 4月 | C6: 5 | D6: 5 | E6: 5 | K6: その他1：デスクトップアイコン位置・既定プリンタの固定 | L6: 2026年 | M6: 4月
B7: 5月 | C7: 3 | D7: 6 | E7: 6 | K7: その他2：テプラ | L7: 2026年 | M7: 4月
B8: 6月 | C8: 3 | D8: 5 | E8: 5 | K8: Wi-Fi接続：製造エリア、自動⇄手動 | L8: 2026年 | M8: 5月
B9: 7月 | C9: 3 | D9: 3 | E9: 3 | K9: TPiCS・PI-navi：現品票発行、タブレット、ハンディターミナル | L9: 2026年 | M9: 5月
B10: 8月 | C10: 1 | D10: 1 | E10: 1 | I10: 2.クラウド環境 | J10: ▶MS365 | K10: 奉行クラウド主担当･TPiCS主担当・営業担当 アカウント導入 | L10: 2026年 | M10: 4月
B11: 9月 | C11: 2 | D11: 3 | E11: 3 | I11: 3.業務データ | J11: ▶事務作業自動化(AI化) | K11: Excel-製造関連 | L11: 2026年 | M11: 5月
A12: 総計 | C12: 27 | D12: 38 | E12: 38 | K12: 議事録 | L12: 2026年 | M12: 5月
H13: 4月 | I13: 3.業務データ | J13: ▶共有フォルダ整備 | K13: 共有フォルダ：可視化ツール➡削除範囲特定 | L13: 2026年 | M13: 4月
K14: 共有フォルダ：コピー移行ツール➡バックアップ・削除 | L14: 2026年 | M14: 5月
K15: 共有フォルダ：検索ツール➡使用頻度順位付け | L15: 2026年 | M15: 6月
I16: 4.ナレッジ | J16: ▶ナレッジ共有（平準化） | K16: マニュアル作成（属人化回避） | L16: 2026年 | M16: 10月
I17: 5.リテラシー向上 | J17: ▶セキュリティ対策・IT基礎知識勉強会 | K17: セキュリティ対策・IT基礎知識勉強会①【？？？】 | L17: 2026年 | M17: 5月
H18: 5月 | I18: 3.業務データ | J18: ▶PDM・PLM環境整備 | K18: サービス調査～開発・品管ヒアリング～具体化～ | L18: 2026年 | M18: 11月
I19: 5.リテラシー向上 | J19: ▶セキュリティ対策・IT基礎知識勉強会 | K19: セキュリティ対策・IT基礎知識勉強会②【？？？】 | L19: 2026年 | M19: 5月
K20: セキュリティ対策・IT基礎知識勉強会③【？？？】 | L20: 2026年 | M20: 6月
H21: 6月 | I21: 3.業務データ | J21: ▶事務作業自動化(AI化) | K21: 日報 改善 | L21: 2026年 | M21: 7月
A22: 年 (完了(目標)) | B22: 月 (完了(目標)) | C22: 個数 / 3区分 | D22: 個数 / 2区分 | E22: 個数 / 1区分 | J22: ▶データ形式標準化 | K22: (▶事務作業自動化(AI化)、▶共有フォルダ整備 進捗に応じて検討開始） | L22: 2026年 | M22: 11月
A23: <2026/4/30 | B23: <2026/4/30 | J23: ▶ペーパーレス化・データ化 | K23: (▶事務作業自動化(AI化)、▶共有フォルダ整備 進捗に応じて検討開始） | L23: 2026年 | M23: 10月
A24: 2026年 | B24: 4月 | C24: 7 | D24: 8 | E24: 8 | H24: 7月 | I24: 2.クラウド環境 | J24: ▶MS365 | K24: 部署別・業務別アカウント 導入 | L24: 2026年 | M24: 9月
B25: 5月 | C25: 7 | D25: 7 | E25: 7 | I25: 3.業務データ | J25: ▶共有フォルダ整備 | K25: 共有フォルダ：データリンク集➡Excelハイパーリンク | L25: 2026年 | M25: 8月
B26: 6月 | C26: 2 | D26: 4 | E26: 4 | K26: 共有フォルダ：定期メンテナンス方法確定 | L26: 2026年 | M26: 8月
B27: 7月 | C27: 1 | D27: 1 | E27: 1 | H27: 8月 | I27: 4.ナレッジ | J27: ▶ナレッジ共有（平準化） | K27: 日報 活用 | L27: 2026年 | M27: 10月
B28: 8月 | C28: 2 | D28: 2 | E28: 2 | H28: 9月 | I28: 2.クラウド環境 | J28: ▶クラウドバックアップ整備 | K28: 専用サービス導入 有無判断➡一次整備完了 | L28: 2026年 | M28: 10月
B29: 9月 | C29: 1 | D29: 1 | E29: 1 | K29: 部署別OneDrive | L29: 2026年 | M29: 10月
B30: 10月 | C30: 5 | D30: 8 | E30: 8
B31: 11月 | C31: 2 | D31: 6 | E31: 6
B32: 12月 | D32: 1 | E32: 1
A33: 総計 | C33: 27 | D33: 38 | E33: 38

Sheet 動作P-
A1: 接続/動作 | B1: アプリ/操作 | C1: 体制/管理 | D1: 勤務拠点 | E1: 部 | F1: 課 | G1: 係 | H1: 年 (回答時期) | I1: 月 (回答時期) | J1: キーワード | K1: No | L1: 原文 | M1: 氏名 | N1: ヒアリング項目 | O1: 対象 | R1: 1 | S1: 以下に、サーバ動作に関する意見を**勤務拠点ごとに整理（要約）**しました。（重複・類似意見は統合しています） | AA1: 2025年9月から、OS・CPUのサポートが終了するパソコンを入れ替え、本社のサーバ本体の設置環境や床下配線の整備、11月10日にシンクライアントサーバをリプレイスしました。
A2: 1 | B2: 1 | C2: 1 | D2: コスメラボラトリー | E2: 技術製造部 | F2: 製造課 | G2: バルク・顆粒 | H2: 2025年 | I2: 3月 | J2: 現品票発行 | K2: 28 | L2: ・ネットの環境か分からないが、現品票の発行（印刷）に時間がかかる。 | M2: 小田晶彦 | N2: (空白) | R2: 2 | S2: ■ 全拠点共通の構造課題（重要） | AA2: 約4ヵ月経過し、リプレイスの前に発生していた不具合・不便な事象に変化があったか否か、お聞かせください。
A3: 1 | B3: 1 | C3: (空白) | D3: 本社 | E3: 技術製造部 | F3: 生産管理課 | G3: 生産管理 | H3: 2025年 | I3: 3月 | J3: ハイパーリンク | K3: 17 | L3: ・エクセルのハイパーリンクはバグりやすいです | M3: 馬場阿弥子 | N3: (空白) | R3: 3 | S3: 各拠点を横断すると、問題は大きく5つに整理できます：
A4: 1 | B4: 1 | C4: (空白) | D4: 本社 | E4: 技術製造部 | F4: 生産管理課 | G4: 生産管理 | H4: 2025年 | I4: 3月 | J4: (空白) | K4: 12 | L4: ・ローカルのブラウザやSkypeの起動が遅い(1～3分くらい掛かる) | M4: 中島和哉 | N4: (空白) | R4: 4 | S4: ① サーバ負荷集中 | AA4: 氏名（フルネーム） | AF4: ↓(ローカル側からコピペしてください。※Windowsスタートメニュー→設定→システム→バージョン情報)
A5: 1 | B5: 1 | C5: (空白) | D5: 本社 | E5: 技術製造部 | F5: 生産管理課 | G5: 生産管理 | H5: 2025年 | I5: 3月 | J5: (空白) | K5: 20 | L5: ・Rグループが重いのとSkypeも終わるタイミングで、チャットやweb会議、スケジュール管理を、 Microsoft系かGoogle系にまとめられたら、各自予定の登録や確認がしやすいかなと思います。 | M5: 馬場阿弥子 | N5: (空白) | R5: 5 | S5: 9時・18時に遅延集中 | AA5: 所属部署 | AB5: 取締役・執行役員 | AF5: ◆デバイスの仕様
A6: 1 | B6: 1 | C6: (空白) | D6: 本社 | E6: 技術製造部 | F6: 生産管理課 | G6: 生産管理事務 | H6: 2025年 | I6: 3月 | J6: PDF | K6: 5 | L6: ・PDFの文字化け(最近落ち着いた気がしますが…) | M6: 東香里 | N6: (空白) | R6: 6 | S6: → リソース不足 or 負荷分散設計不足 | AB6: 研究開発部 研究開発課 | AF6: デバイス名
A7: 1 | B7: 1 | C7: (空白) | D7: 本社 | E7: 技術製造部 | F7: 生産管理課 | G7: 生産管理事務 | H7: 2025年 | I7: 3月 | J7: PDF | K7: 6 | L7: ・概ねPDFが重い気がします | M7: 東香里 | N7: (空白) | R7: 7 | S7: ② シンクライアント依存 | AB7: 品質保証部 品質管理課 | AF7: プロセッサ
A8: 1 | B8: 1 | C8: (空白) | D8: 本社 | E8: 技術製造部 | F8: 生産管理課 | G8: 生産管理事務 | H8: 2025年 | I8: 3月 | J8: ハイパーリンク | K8: 2 | L8: ・定期的にハイパーリンクがリンクしなくなる。 | M8: 徳永彩花 | N8: (空白) | R8: 8 | S8: 全拠点で遅延・切断・フリーズ | AB8: 技術製造部 製造課 液体 | AF8: 実装 RAM
A9: 1 | B9: 1 | C9: (空白) | D9: 本社 | E9: 技術製造部 | F9: 生産管理課 | G9: 生産管理事務 | H9: 2025年 | I9: 3月 | J9: ハイパーリンク | K9: 4 | L9: ・たまにハイパーリンクが死亡する(どういった場合かは不明。突然発生する) | M9: 東香里 | N9: (空白) | R9: 9 | S9: → 基盤構造のボトルネック | AB9: 技術製造部 製造課 粉体 | AF9: デバイス ID
A10: 1 | B10: 1 | C10: (空白) | D10: 本社 | E10: 技術製造部 | F10: 生産管理課 | G10: 生産管理事務 | H10: 2025年 | I10: 3月 | J10: (空白) | K10: 1 | L10: ・サーバーのフリーズが多い、ローカルのSkype立ち上がりなど少し遅い印象 | M10: 徳永彩花 | N10: (空白) | R10: 10 | S10: ③ ネットワーク品質 | AB10: 技術製造部 製造課 バルク・顆粒 | AF10: プロダクト ID
A11: 1 | B11: 1 | C11: (空白) | D11: コスメラボラトリー | E11: 研究開発部 | F11: 研究開発課 | G11: - | H11: 2025年 | I11: 3月 | J11: Excel | K11: 62 | L11: ・一定の手順で必ずエクセルとワードが落ちることがある。 | M11: 近藤雅人 | N11: (空白) | R11: 11 | S11: 回線遅延・切断 | AB11: 技術製造部 製造課 充填包装 | AF11: システムの種類
A12: 1 | B12: 1 | C12: (空白) | D12: コスメラボラトリー | E12: 研究開発部 | F12: 研究開発課 | G12: - | H12: 2025年 | I12: 3月 | J12: Excel | K12: 90 | L12: ・Excelの動きが遅い、フリーズして消えることがある | M12: 橋口千聖 | N12: (空白) | R12: 12 | S12: → 拠点間帯域 or WAN問題 | AB12: 技術製造部 生産管理課 生産管理 | AF12: ペンとタッチ
A13: 1 | B13: 1 | C13: (空白) | D13: コスメラボラトリー | E13: 研究開発部 | F13: 研究開発課 | G13: - | H13: 2025年 | I13: 3月 | J13: Excel・PDF | K13: 73 | L13: ・エクセル、PDF使用時は遅くなりやすい。 | M13: 直木美佐子 | N13: (空白) | R13: 13 | S13: ④ 端末性能差 | AB13: 技術製造部 生産管理課 生産管理事務 | AF13: ◆OSの仕様
A14: 1 | B14: 1 | C14: (空白) | D14: コスメラボラトリー | E14: 研究開発部 | F14: 研究開発課 | G14: - | H14: 2025年 | I14: 3月 | J14: Excel・Word | K14: 60 | L14: ・エクセル・ワードにて、タイピングした内容が反映されるまでのタイムラグがかなりある時がある。 | M14: 近藤雅人 | N14: (空白) | R14: 14 | S14: 古いPC・タブレット | AB14: 技術製造部 生産管理課 物流 | AF14: エディション
A15: 1 | B15: 1 | C15: (空白) | D15: コスメラボラトリー | E15: 研究開発部 | F15: 研究開発課 | G15: - | H15: 2025年 | I15: 3月 | J15: Excel・Word | K15: 68 | L15: ・Word、EXcel使用時に急に落ちる。 | M15: 山下基宏 | N15: (空白) | R15: 15 | S15: → クライアント側処理不足 | AB15: 技術製造部 製造課 パート事務 | AF15: バージョン
A16: 1 | B16: 1 | C16: (空白) | D16: コスメラボラトリー | E16: 研究開発部 | F16: 研究開発課 | G16: - | H16: 2025年 | I16: 3月 | J16: Outlook | K16: 59 | L16: ・朝立ち上げ時、アウトルックの起動に5分程かかる | M16: 近藤雅人 | N16: (空白) | R16: 16 | S16: ⑤ アプリ・データ肥大化 | AB16: 管理部 管理課 | AF16: インストール日
A17: 1 | B17: 1 | C17: (空白) | D17: コスメラボラトリー | E17: 研究開発部 | F17: 研究開発課 | G17: - | H17: 2025年 | I17: 3月 | J17: Outlook | K17: 67 | L17: ・Outlook使用時に急に落ちる。 | M17: 山下基宏 | N17: (空白) | R17: 17 | S17: Excel／PDF／Outlook遅延 | AB17: EC事業部 EC事業課 | AF17: OS ビルド
A18: 1 | B18: 1 | C18: (空白) | D18: コスメラボラトリー | E18: 研究開発部 | F18: 研究開発課 | G18: - | H18: 2025年 | I18: 3月 | J18: Outlook | K18: 89 | L18: ・Outlookの動きが遅い、フリーズする | M18: 橋口千聖 | N18: (空白) | R18: 18 | S18: → データ量増加＋最適化不足 | AB18: 企画営業部 営業課 | AF18: シリアル番号
A19: 1 | B19: 1 | C19: (空白) | D19: コスメラボラトリー | E19: 研究開発部 | F19: 研究開発課 | G19: - | H19: 2025年 | I19: 3月 | J19: PDF | K19: 82 | L19: ・最近PDFの立ち上がりが遅い | M19: 矢野恵 | N19: (空白) | R19: 19 | AB19: 企画営業部 企画課 | AF19: エクスペリエンス
A20: 1 | B20: 1 | C20: (空白) | D20: コスメラボラトリー | E20: 研究開発部 | F20: 研究開発課 | G20: - | H20: 2025年 | I20: 3月 | J20: ブラウザ | K20: 91 | L20: ・インターネット検索に時間がかかる、サーバー外でも時間がかかる | M20: 橋口千聖 | N20: (空白) | R20: 20 | S20: ■ まとめ（経営視点） | AA20: 常勤拠点 | AB20: 本社
A21: 1 | B21: 1 | C21: (空白) | D21: コスメラボラトリー | E21: 研究開発部 | F21: 研究開発課 | G21: - | H21: 2025年 | I21: 3月 | J21: メール検索 | K21: 83 | L21: ・outlookのメールの検索が遅い | M21: 矢野恵 | N21: (空白) | R21: 21 | S21: 最重度：コスメラボラトリー（研究開発） | AB21: ラボラトリー | AF21: ◆無線接続先
A22: 1 | B22: 1 | C22: (空白) | D22: コスメラボラトリー | E22: 品質保証部 | F22: 品質管理課 | G22: - | H22: 2025年 | I22: 3月 | J22: Explorer | K22: 86 | L22: ・サーバーに関係あるか分かりませんが、開いている全てのエクスプローラーが勝手に閉じる | M22: 西村穂乃果 | N22: (空白) | R22: 22 | S22: 次点：本社・コスメファクトリー | AB22: ファクトリー | AF22: Wi-Fi接続 SSID (メイン)
A23: 1 | B23: 1 | C23: (空白) | D23: コスメラボラトリー | E23: 技術製造部 | F23: 製造課 | G23: バルク・顆粒 | H23: 2025年 | I23: 3月 | J23: TPiCS・PI-navi | K23: 29 | L23: ・朝の９時以外でもメールやTPiCS・PI-naviが遅い時がある。時間は見てないです。あきらめて製造に戻る時もあります。 | M23: 小田晶彦 | N23: (空白) | R23: 23 | S23: 構造問題：インフラ設計全体（サーバ＋回線＋シンクラ） | AB23: 第一倉庫 | AF23: Wi-Fi接続 SSID (サブ1)
A24: 1 | B24: 1 | C24: (空白) | D24: コスメラボラトリー | E24: EC事業部 | F24: EC事業課 | G24: - | H24: 2025年 | I24: 3月 | J24: Excel | K24: 57 | L24: エクセルの操作が固まりやすい | M24: 大前道仁 | N24: (空白) | R24: 24 | S24: 👉 単なる「PCが遅い」ではなく | AB24: 東京営業所 | AF24: Wi-Fi接続 SSID (サブ2)
A25: 1 | B25: 1 | C25: (空白) | D25: コスメラボラトリー | E25: EC事業部 | F25: EC事業課 | G25: - | H25: 2025年 | I25: 3月 | J25: ブラウザ | K25: 50 | L25: ブラウザ処理の負荷に耐えれていない | M25: 中土陽介 | N25: (空白) | R25: 25 | S25: “インフラ設計の限界に到達している状態” | AA25: 仮想サーバ | AB25: A | AF25: Wi-Fi接続 SSID (サブ3)
A26: 1 | B26: 1 | C26: (空白) | D26: コスメラボラトリー | E26: EC事業部 | F26: EC事業課 | G26: - | H26: 2025年 | I26: 3月 | J26: ブラウザ | K26: 56 | L26: 受注が多い日に受注管理システム（ブラウザ）からデータをDLすると重たい | M26: 大前道仁 | N26: (空白) | R26: 26 | AB26: B | AF26: Wi-Fi接続 SSID (サブ4)
A27: 1 | B27: 1 | C27: (空白) | D27: コスメラボラトリー | E27: EC事業部 | F27: EC事業課 | G27: - | H27: 2025年 | I27: 3月 | J27: ブラウザ | K27: 58 | L27: ブラウザ上の業務が多い中、固まることで遅延してしまう。 | M27: 酒井絢音 | N27: (空白) | R27: 27 | S27: ■ 勤務拠点別まとめ（サーバ動作） | AB27: C | AF27: Wi-Fi接続 SSID (サブ5)
A28: 1 | B28: (空白) | C28: 1 | D28: 本社 | E28: 技術製造部 | F28: 製造課 | G28: 粉体 | H28: 2025年 | I28: 7月 | J28: 迷惑メール | K28: 376 | L28: 迷惑メールが増えている。今でもフリーズすることがある。 | M28: 内藤恭介 | N28: ⑥その他(自由意見) | R28: 28 | S28: ① 本社
A29: 1 | B29: (空白) | C29: 1 | D29: 第一倉庫 | E29: 技術製造部 | F29: 生産管理課 | G29: 物流 | H29: 2025年 | I29: 3月 | J29: ハンディターミナル | K29: 15 | L29: ・ハンディの動作反応が年々遅くなっている→データ蓄積されているため？ | M29: 池田悦彰 | N29: (空白) | R29: 29 | S29: ● 主な課題 | AA29: シンクライアントサーバについて
A30: 1 | B30: (空白) | C30: (空白) | D30: 本社 | E30: 管理部 | F30: 管理課 | G30: - | H30: 2025年 | I30: 3月 | J30: デスクトップアイコン | K30: 39 | L30: ・会計処理をする際、管理部用のノートＰＣでサーバー接続しCSVデータを取り込んでいますが、デスクトップPCに戻りログインするとデスクトップ上のアイコンの配列がバラバラになり少しストレスです | M30: 図書杏子 | N30: (空白) | R30: 30 | S30: サーバーフリーズ・不安定 | AA30: ログインの時刻+接続時間について | AD30: 1 不具合・不便を全く感じない
A31: 1 | B31: (空白) | C31: (空白) | D31: 本社 | E31: 管理部 | F31: 管理課 | G31: - | H31: 2025年 | I31: 3月 | J31: ブラウザ | K31: 47 | L31: ･アマゾンサイトなどへ接続している時、サイト内の動きがとても遅いです。 | M31: 丸中都 | N31: (空白) | R31: 31 | S31: フリーズが多い／突然切断／再ログイン頻発 | AA31: 9時・18時 | AD31: 2 殆ど感じない
A32: 1 | B32: (空白) | C32: (空白) | D32: 本社 | E32: 管理部 | F32: 管理課 | G32: - | H32: 2025年 | I32: 3月 | J32: プリンタ既定 | K32: 38 | L32: ・一定期間作業していない時（昼休みなど）ログイン画面が表示され入るとプリンター指定が解除されて毎回ＰＤＦ指定になる | M32: 図書杏子 | N32: (空白) | R32: 32 | S32: 起動・接続遅延 | AA32: 昼休み | AD32: 3 たまに感じる
A33: 1 | B33: (空白) | C33: (空白) | D33: 本社 | E33: 管理部 | F33: 管理課 | G33: - | H33: 2025年 | I33: 3月 | J33: 共有フォルダ | K33: 41 | L33: ・毎日最初の一回共有フォルダにはじかれる | M33: 越智絵美子 | N33: (空白) | R33: 33 | S33: PC起動・シンクラ接続に時間（約3〜6分） | AA33: それ以外の時間帯 | AD33: 4 週に1～2回はある／2～3分以上かかる
A34: 1 | B34: (空白) | C34: (空白) | D34: 本社 | E34: 管理部 | F34: 管理課 | G34: - | H34: 2025年 | I34: 3月 | J34: (空白) | K34: 45 | L34: ・昔よりは改善されてますがPCが固まったり遅かったりする | M34: 越智絵美子 | N34: (空白) | R34: 34 | S34: 共有フォルダ接続不良 | AA34: 常勤拠点での接続の状態について | AD34: 5 リプレイス前と変わっていない／5分以上かかる
A35: 1 | B35: (空白) | C35: (空白) | D35: 本社 | E35: 管理部 | F35: 管理課 | G35: - | H35: 2025年 | I35: 3月 | J35: (空白) | K35: 46 | L35: ・事務長がサーバーになかなか入れないときがある | M35: 越智絵美子 | N35: (空白) | R35: 35 | S35: 初回アクセスで弾かれる／ログインできない | AA35: ログインできない
A36: 1 | B36: (空白) | C36: (空白) | D36: 本社 | E36: 管理部 | F36: 管理課 | G36: - | H36: 2025年 | I36: 3月 | J36: (空白) | K36: 48 | L36: ･突然サーバーからはじき出される。ログインしなおすと作業途中の画面には戻れます。 | M36: 丸中都 | N36: (空白) | R36: 36 | S36: ブラウザ・アプリ遅延 | AA36: 突然切断される・再ログインする
A37: 1 | B37: (空白) | C37: (空白) | D37: 本社 | E37: 技術製造部 | F37: 生産管理課 | G37: 生産管理 | H37: 2025年 | I37: 3月 | J37: (空白) | K37: 10 | L37: ・ローカル、サーバー共にフリーズが多い | M37: 中島和哉 | N37: (空白) | R37: 37 | S37: Skype・ブラウザ起動遅い（1〜3分） | AA37: 画面が真っ暗になる
A38: 1 | B38: (空白) | C38: (空白) | D38: 本社 | E38: 技術製造部 | F38: 生産管理課 | G38: 生産管理 | H38: 2025年 | I38: 3月 | J38: (空白) | K38: 11 | L38: ・パソコンの起動が遅く、シンクラの接続にも時間が掛かる、電源入～デスクトップの画面表示まで約3分30秒、Aサーバー接続アイコン選択～シンクラ画面まで約2分30秒 | M38: 中島和哉 | N38: (空白) | R38: 38 | S38: リンク・ファイル不具合 | AA38: フリーズする
A39: 1 | B39: (空白) | C39: (空白) | D39: 本社 | E39: 技術製造部 | F39: 生産管理課 | G39: 生産管理 | H39: 2025年 | I39: 3月 | J39: (空白) | K39: 19 | L39: ・サーバーのフリーズが多い | M39: 馬場阿弥子 | N39: (空白) | R39: 39 | S39: ハイパーリンク切れ／PDF重い・文字化け | AA39: 動作が重い
A40: 1 | B40: (空白) | C40: (空白) | D40: 本社 | E40: 技術製造部 | F40: 生産管理課 | G40: 生産管理 | H40: 2025年 | I40: 3月 | J40: (空白) | K40: 22 | L40: ・ローカルのブラウザやSkypeの起動が遅い(1～3分くらい掛かる) | M40: 島田智章 | N40: (空白) | R40: 40 | S40: ● 特徴 | AA40: 製造エリアでの接続の状態について（製造課メンバーのみ）
...

Sheet MS365
D1: 46087 | E1: 鳥山主任 | K1: 46079 | L1: 髙野
B2: 奉行担当関連 | K2: 【管理/共有】
C3: ①Q美ワールド側の生産管理課アカウントの有無 | K3: 図書杏子 SSC/Q美(売り) E
D4: 東さんのアカウントのみあり | K4: 越智絵美子 SSC/Q美(買い,棚卸) E
C5: ②管理部がExcelを必要としない場合の作業環境(サーバーorローカル) | K5: 丸中都 SSC？/Q美 E
D6: サーバーで作業を行っている | K6: ∟3+鳥山
C7: ③シンコーサイエンス側の「売る」「買う」の処理分担
D8: 「売る」は図書主任、「買う」は越智リーダー | K8: 【生産管理1/共有】
C9: ④丸中さんがシンコーサイエンス側を触るか否か | K9: 馬場阿弥子 SSC EE
D10: 森下産業の原料受注に対する発注処理を行うことがある | K10: 東香里 SSC EE
C11: ⑤Q美ワールドの原価登録担当 | K11: 徳永彩花 SSC EE
D12: 丸中さん | K12: ∟3+鳥山
C13: ⑥受注～売りの登録での2重登録
D14: 奉行クラウドにおいては、売価が変更となった場合 | K14: 【生産管理2/共有】
D15: 売りの処理時に売価を変更する | K15: 鳥山一洋 SSC EE
D16: 受注側にも反映されるので、2重登録とはなっていない | K16: 中島和哉 SSC E
C17: ⑦Q美、シンコーの受注～売りの登録の流れ | K17: 島田智章 SSC E
D18: Q美受注～売りまでの登録を丸中さんが行い | K18: +物流?
D19: 一か月分まとめたQ美原価とシンコー原価を図書主任に提示
D20: その情報をもとに図書主任がシンコーからQ美に | K20: 【WEB/共有】
D21: 請求処理を行う | K21: 中土陽介
K22: 髙野愛子
B23: 生産管理課のMS365導入関連 | K23: 中村剛
C24: ・MS365の2アカウントに対する振り分け
D25: ①島田主任、馬場リーダー、中島くん、鳥山 | K25: 【営業/個別】
D26: ②東さん、徳永さん、池田リーダー(タブレット)、鳥山 | K26: 吉村善成
D27: ※池田リーダーについてはMS365導入後、実運用でどのように生かせるのか検証を進める | K27: 南光彦
K28: 橋本悠司
K31: サーバ奉行 システム側の動作保証の問題だけなので、残しておく方向
K33: 仕入発注 奉行→TPiCS CSV又はExcel吐き出してO→マクロ加工してT→取り込む＠生管
K34: 受注登録 TPiCS→奉行 出荷先-注意事項(追加項目⇄1項目でテンプレ化) →取り込む＠管理
K35: 原価 TPiCS→原価表→奉行 マクロ加工してO→取り込む＠生管？管理？
K36: 出荷/出庫 TPiCS→奉行 検討(預かり在庫の識別) →取り込む＠生管？管理？

Sheet 抜粋P
A3: キーワード | B3: 合計 / 意識/姿勢 | C3: 個数 / 原文
A4: AI・自動化 | B4: 5 | C4: 1
A5: Excel | C5: 3
A6: Excel・PDF | C6: 1
A7: Excel・Word | C7: 2
A8: Excel-製造関連 | B8: 30 | C8: 7
A9: Explorer | C9: 1
A10: Lanscope | B10: 5 | C10: 1
A11: Outlook | B11: 4 | C11: 4
A12: PDF | C12: 3
A13: TPiCS・PI-navi | C13: 1
A14: Wi-Fi設定 | C14: 1
A15: タブレット | C15: 1
A16: データ化 | B16: 4 | C16: 1
A17: デスクトップアイコン | C17: 1
A18: テプラ | C18: 1
A19: デュアルモニター | C19: 2
A20: ハイパーリンク | C20: 3
A21: バックアップ | C21: 1
A22: ハンディターミナル | C22: 1
A23: ブラウザ | C23: 5
A24: プリンタ既定 | C24: 3
A25: マニュアル・ナレッジ | B25: 92 | C25: 21
A26: マニュアル作成 | B26: 5 | C26: 1
A27: メール検索 | C27: 4
A28: メール振分 | C28: 2
A29: リアルタイム共有 | B29: 5 | C29: 1
A30: ワークフロー | B30: 9 | C30: 2
A31: 案件タスク管理 | B31: 5 | C31: 1
A32: 議事録 | B32: 16 | C32: 4
A33: 拠点外作業 | B33: 13 | C33: 3
A34: 共有フォルダ | B34: 35 | C34: 9
A35: 現品票発行 | C35: 1
A36: 最適化・高速化 | C36: 1
A37: 参照先整備 | B37: 5 | C37: 1
A38: 時間帯 | B38: 3 | C38: 3
A39: 自動通知 | B39: 8 | C39: 2
A40: 日報改善 | B40: 5 | C40: 1
A41: 日報活用 | B41: 5 | C41: 1
A42: 迷惑メール | B42: 43 | C42: 11
...

Sheet 完了CP
A2: サーバ/端末 | B2: 1
A3: 完了 | B3: (空白)
A5: 接続/動作 | B5: アプリ/操作 | C5: 体制/管理 | D5: 勤務拠点 | E5: 部 | F5: 課 | G5: 係 | H5: 年 (回答時期) | I5: 月 (回答時期) | J5: キーワード | K5: No | L5: 原文 | M5: 氏名 | N5: ヒアリング項目
A6: 1 | B6: 1 | C6: 1 | D6: コスメラボラトリー | E6: 技術製造部 | F6: 製造課 | G6: バルク・顆粒 | H6: 2025年 | I6: 3月 | J6: 現品票発行 | K6: 28 | L6: ・ネットの環境か分からないが、現品票の発行（印刷）に時間がかかる。 | M6: 小田晶彦 | N6: (空白)
A7: 1 | B7: 1 | C7: (空白) | D7: 本社 | E7: 技術製造部 | F7: 生産管理課 | G7: 生産管理 | H7: 2025年 | I7: 3月 | J7: ハイパーリンク | K7: 17 | L7: ・エクセルのハイパーリンクはバグりやすいです | M7: 馬場阿弥子 | N7: (空白)
A8: 1 | B8: 1 | C8: (空白) | D8: 本社 | E8: 技術製造部 | F8: 生産管理課 | G8: 生産管理 | H8: 2025年 | I8: 3月 | J8: (空白) | K8: 12 | L8: ・ローカルのブラウザやSkypeの起動が遅い(1～3分くらい掛かる) | M8: 中島和哉 | N8: (空白)
A9: 1 | B9: 1 | C9: (空白) | D9: 本社 | E9: 技術製造部 | F9: 生産管理課 | G9: 生産管理 | H9: 2025年 | I9: 3月 | J9: (空白) | K9: 20 | L9: ・Rグループが重いのとSkypeも終わるタイミングで、チャットやweb会議、スケジュール管理を、 Microsoft系かGoogle系にまとめられたら、各自予定の登録や確認がしやすいかなと思います。 | M9: 馬場阿弥子 | N9: (空白)
A10: 1 | B10: 1 | C10: (空白) | D10: 本社 | E10: 技術製造部 | F10: 生産管理課 | G10: 生産管理事務 | H10: 2025年 | I10: 3月 | J10: PDF | K10: 5 | L10: ・PDFの文字化け(最近落ち着いた気がしますが…) | M10: 東香里 | N10: (空白)
A11: 1 | B11: 1 | C11: (空白) | D11: 本社 | E11: 技術製造部 | F11: 生産管理課 | G11: 生産管理事務 | H11: 2025年 | I11: 3月 | J11: PDF | K11: 6 | L11: ・概ねPDFが重い気がします | M11: 東香里 | N11: (空白)
A12: 1 | B12: 1 | C12: (空白) | D12: 本社 | E12: 技術製造部 | F12: 生産管理課 | G12: 生産管理事務 | H12: 2025年 | I12: 3月 | J12: ハイパーリンク | K12: 2 | L12: ・定期的にハイパーリンクがリンクしなくなる。 | M12: 徳永彩花 | N12: (空白)
A13: 1 | B13: 1 | C13: (空白) | D13: 本社 | E13: 技術製造部 | F13: 生産管理課 | G13: 生産管理事務 | H13: 2025年 | I13: 3月 | J13: ハイパーリンク | K13: 4 | L13: ・たまにハイパーリンクが死亡する(どういった場合かは不明。突然発生する) | M13: 東香里 | N13: (空白)
A14: 1 | B14: 1 | C14: (空白) | D14: 本社 | E14: 技術製造部 | F14: 生産管理課 | G14: 生産管理事務 | H14: 2025年 | I14: 3月 | J14: (空白) | K14: 1 | L14: ・サーバーのフリーズが多い、ローカルのSkype立ち上がりなど少し遅い印象 | M14: 徳永彩花 | N14: (空白)
A15: 1 | B15: 1 | C15: (空白) | D15: コスメラボラトリー | E15: 研究開発部 | F15: 研究開発課 | G15: - | H15: 2025年 | I15: 3月 | J15: Excel | K15: 62 | L15: ・一定の手順で必ずエクセルとワードが落ちることがある。 | M15: 近藤雅人 | N15: (空白)
A16: 1 | B16: 1 | C16: (空白) | D16: コスメラボラトリー | E16: 研究開発部 | F16: 研究開発課 | G16: - | H16: 2025年 | I16: 3月 | J16: Excel | K16: 90 | L16: ・Excelの動きが遅い、フリーズして消えることがある | M16: 橋口千聖 | N16: (空白)
A17: 1 | B17: 1 | C17: (空白) | D17: コスメラボラトリー | E17: 研究開発部 | F17: 研究開発課 | G17: - | H17: 2025年 | I17: 3月 | J17: Excel・PDF | K17: 73 | L17: ・エクセル、PDF使用時は遅くなりやすい。 | M17: 直木美佐子 | N17: (空白)
A18: 1 | B18: 1 | C18: (空白) | D18: コスメラボラトリー | E18: 研究開発部 | F18: 研究開発課 | G18: - | H18: 2025年 | I18: 3月 | J18: Excel・Word | K18: 60 | L18: ・エクセル・ワードにて、タイピングした内容が反映されるまでのタイムラグがかなりある時がある。 | M18: 近藤雅人 | N18: (空白)
... A31: 1 | B31: 1 | C31: (空白) | D31: コスメラボラトリー | E31: EC事業部 | F31: EC事業課 | G31: - | H31: 2025年 | I31: 3月 | J31: ブラウザ | K31: 58 | L31: ブラウザ上の業務が多い中、固まることで遅延してしまう。 | M31: 酒井絢音 | N31: (空白)
A32: 1 | B32: (空白) | C32: 1 | D32: 本社 | E32: 技術製造部 | F32: 製造課 | G32: 粉体 | H32: 2025年 | I32: 7月 | J32: 迷惑メール | K32: 376 | L32: 迷惑メールが増えている。今でもフリーズすることがある。 | M32: 内藤恭介 | N32: ⑥その他(自由意見)
A33: 1 | B33: (空白) | C33: 1 | D33: 第一倉庫 | E33: 技術製造部 | F33: 生産管理課 | G33: 物流 | H33: 2025年 | I33: 3月 | J33: ハンディターミナル | K33: 15 | L33: ・ハンディの動作反応が年々遅くなっている→データ蓄積されているため？ | M33: 池田悦彰 | N33: (空白)
A34: 1 | B34: (空白) | C34: (空白) | D34: 本社 | E34: 管理部 | F34: 管理課 | G34: - | H34: 2025年 | I34: 3月 | J34: デスクトップアイコン | K34: 39 | L34: ・会計処理をする際、管理部用のノートＰＣでサーバー接続しCSVデータを取り込んでいますが、デスクトップPCに戻りログインするとデスクトップ上のアイコンの配列がバラバラになり少しストレスです | M34: 図書杏子 | N34: (空白)
A35: 1 | B35: (空白) | C35: (空白) | D35: 本社 | E35: 管理部 | F35: 管理課 | G35: - | H35: 2025年 | I35: 3月 | J35: ブラウザ | K35: 47 | L35: ･アマゾンサイトなどへ接続している時、サイト内の動きがとても遅いです。 | M35: 丸中都 | N35: (空白)
A36: 1 | B36: (空白) | C36: (空白) | D36: 本社 | E36: 管理部 | F36: 管理課 | G36: - | H36: 2025年 | I36: 3月 | J36: プリンタ既定 | K36: 38 | L36: ・一定期間作業していない時（昼休みなど）ログイン画面が表示され入るとプリンター指定が解除されて毎回ＰＤＦ指定になる | M36: 図書杏子 | N36: (空白)
A37: 1 | B37: (空白) | C37: (空白) | D37: 本社 | E37: 管理部 | F37: 管理課 | G37: - | H37: 2025年 | I37: 3月 | J37: 共有フォルダ | K37: 41 | L37: ・毎日最初の一回共有フォルダにはじかれる | M37: 越智絵美子 | N37: (空白)
A38: 1 | B38: (空白) | C38: (空白) | D38: 本社 | E38: 管理部 | F38: 管理課 | G38: - | H38: 2025年 | I38: 3月 | J38: (空白) | K38: 45 | L38: ・昔よりは改善されてますがPCが固まったり遅かったりする | M38: 越智絵美子 | N38: (空白)
A39: 1 | B39: (空白) | C39: (空白) | D39: 本社 | E39: 管理部 | F39: 管理課 | G39: - | H39: 2025年 | I39: 3月 | J39: (空白) | K39: 46 | L39: ・事務長がサーバーになかなか入れないときがある | M39: 越智絵美子 | N39: (空白)
A40: 1 | B40: (空白) | C40: (空白) | D40: 本社 | E40: 管理部 | F40: 管理課 | G40: - | H40: 2025年 | I40: 3月 | J40: (空白) | K40: 48 | L40: ･突然サーバーからはじき出される。ログインしなおすと作業途中の画面には戻れます。 | M40: 丸中都 | N40: (空白)
A41: 1 | B41: (空白) | C41: (空白) | D41: 本社 | E41: 技術製造部 | F41: 生産管理課 | G41: 生産管理 | H41: 2025年 | I41: 3月 | J41: (空白) | K41: 10 | L41: ・ローカル、サーバー共にフリーズが多い | M41: 中島和哉 | N41: (空白)
A42: 1 | B42: (空白) | C42: (空白) | D42: 本社 | E42: 技術製造部 | F42: 生産管理課 | G42: 生産管理 | H42: 2025年 | I42: 3月 | J42: (空白) | K42: 11 | L42: ・パソコンの起動が遅く、シンクラの接続にも時間が掛かる、電源入～デスクトップの画面表示まで約3分30秒、Aサーバー接続アイコン選択～シンクラ画面まで約2分30秒 | M42: 中島和哉 | N42: (空白)
A43: 1 | B43: (空白) | C43: (空白) | D43: 本社 | E43: 技術製造部 | F43: 生産管理課 | G43: 生産管理 | H43: 2025年 | I43: 3月 | J43: (空白) | K43: 19 | L43: ・サーバーのフリーズが多い | M43: 馬場阿弥子 | N43: (空白)
A44: 1 | B44: (空白) | C44: (空白) | D44: 本社 | E44: 技術製造部 | F44: 生産管理課 | G44: 生産管理 | H44: 2025年 | I44: 3月 | J44: (空白) | K44: 22 | L44: ・ローカルのブラウザやSkypeの起動が遅い(1～3分くらい掛かる) | M44: 島田智章 | N44: (空白)
A45: 1 | B45: (空白) | C45: (空白) | D45: 本社 | E45: 技術製造部 | F45: 生産管理課 | G45: 生産管理 | H45: 2025年 | I45: 3月 | J45: (空白) | K45: 23 | L45: ・パソコンの起動が遅く、シンクラの接続にも時間が掛かる(中島くんと同等の所要時間) ※島田主任と中島くんのPCスペックは同等です | M45: 島田智章 | N45: (空白)
... A83: 1 | B83: (空白) | C83: (空白) | D83: 東京営業所 | E83: 企画営業部 | F83: 営業課 | G83: - | H83: 2025年 | I83: 6月 | J83: マニュアル・ナレッジ | K83: 119 | L83: サーバーやアプリに繋がらないなどの時の簡易トラブル対処マニュアル作成 | M83: 橋本悠司 | N83: セキュリティ
A84: (空白) | B84: 1 | C84: 1 | D84: 本社 | E84: 技術製造部 | F84: 生産管理課 | G84: 生産管理 | H84: 2025年 | I84: 6月 | J84: 迷惑メール | K84: 103 | L84: 各ユーザーレベルで必要な知識はマニュアルが欲しいですが、 OJTはお願したいです。特にセキュリティはハードルが高いと感じてます・・・ 個人的には、メールは迷惑メールが来てるのと、SPAM認識されてるメールも多く、 何かしら各個人で対応ができるのか等、教えて頂きたいです。 | M84: 馬場阿弥子 | N84: セキュリティ
A85: (空白) | B85: (空白) | C85: 1 | D85: 本社 | E85: 品質保証部 | F85: 品質管理課 | G85: - | H85: 2025年 | I85: 7月 | J85: 迷惑メール | K85: 291 | L85: 迷惑メールが多量に届くためブロックする方法や対策について相談を行いたい | M85: 野村秀太朗 | N85: ④セキュリティ
A86: (空白) | B86: (空白) | C86: 1 | D86: 本社 | E86: 技術製造部 | F86: 生産管理課 | G86: 生産管理 | H86: 2025年 | I86: 3月 | J86: デュアルモニター | K86: 13 | L86: ・複数のデータを見ながら処理を進めることが多いので、デュアルモニターだと作業効率が上がりそうです | M86: 中島和哉 | N86: (空白)
A87: (空白) | B87: (空白) | C87: 1 | D87: 本社 | E87: 技術製造部 | F87: 生産管理課 | G87: 生産管理 | H87: 2025年 | I87: 3月 | J87: デュアルモニター | K87: 18 | L87: ・デュアルモニターの対応ができてデータを並べられたら、効率は上がる可能性あります。 例えば、製造予定とTPCIS等を並べて確認や、充填バルクの製造予定並べて見れたら、画面が広分確認はしやすいです。 | M87: 馬場阿弥子 | N87: (空白)
A88: (空白) | B88: (空白) | C88: 1 | D88: 本社 | E88: 技術製造部 | F88: 生産管理課 | G88: 生産管理 | H88: 2025年 | I88: 7月 | J88: 迷惑メール | K88: 281 | L88: 迷惑メールが一定数あったり、必要なメールがSPAM認定されてるので、エラーとかで届かない等にならないかは気になる | M88: 馬場阿弥子 | N88: ④セキュリティ
A89: (空白) | B89: (空白) | C89: 1 | D89: 本社 | E89: 技術製造部 | F89: 生産管理課 | G89: 生産管理 | H89: 2025年 | I89: 7月 | J89: 迷惑メール | K89: 287 | L89: ウイルス対策と迷惑メールはなくしてほしい | M89: 島田智章 | N89: ④セキュリティ
A90: (空白) | B90: (空白) | C90: 1 | D90: 本社 | E90: 技術製造部 | F90: 生産管理課 | G90: 生産管理事務 | H90: 2025年 | I90: 7月 | J90: 迷惑メール | K90: 284 | L90: 最近迷惑メールが来る頻度が増えている。 | M90: 徳永彩花 | N90: ④セキュリティ
A91: (空白) | B91: (空白) | C91: 1 | D91: 本社 | E91: 技術製造部 | F91: 生産管理課 | G91: 生産管理事務 | H91: 2025年 | I91: 7月 | J91: 迷惑メール | K91: 288 | L91: 毎日迷惑メールが来る。(2～3件) | M91: 東香里 | N91: ④セキュリティ
...

Sheet データベース
E1: 1短期：すぐできる | P1: 1無し | R1: 561
E2: 2中期：現状からできる | P2: 2低い
E3: 3長期：環境整備から | P3: 3普通
P4: 4有り | R4: 受動的、限定的
P5: 5高い | R5: 能動的、広範囲
A6: No | B6: 回答時期 | C6: 計画No | D6: 計画着手 | E6: 期間 | F6: ヒアリング項目 | G6: キーワード | H6: サーバ/端末 | I6: 接続/動作 | J6: アプリ/操作 | K6: 体制/管理 | L6: 基礎向上 | M6: マニュアル/ナレッジ | N6: AI/DB化 | O6: 課題/提案 | P6: 意識/姿勢 | Q6: 候補者 | R6: 原文 | S6: 主担当 | T6: 対策/解決 | U6: 完了 | V6: 氏名 | W6: 部 | X6: 課 | Y6: 係 | Z6: 勤務拠点 | AA6: 接続エリア
A7: 1 | B7: 45746 | H7: 1 | I7: 1 | J7: 1 | R7: ・サーバーのフリーズが多い、ローカルのSkype立ち上がりなど少し遅い印象 | V7: 徳永彩花 | W7: =VLOOKUP(V7,名簿!A:L,3,FALSE) -> 技術製造部 | X7: =VLOOKUP(V7,名簿!A:L,4,FALSE) -> 生産管理課 | Y7: =VLOOKUP(V7,名簿!A:L,5,FALSE) -> 生産管理事務 | Z7: =VLOOKUP(V7,名簿!A:L,11,FALSE) -> 本社 | AA7: =VLOOKUP(V7,名簿!A:L,12,FALSE) -> 3F/シンク前
A8: 2 | B8: 45746 | G8: ハイパーリンク | H8: 1 | I8: 1 | J8: 1 | R8: ・定期的にハイパーリンクがリンクしなくなる。 | V8: 徳永彩花 | W8: =VLOOKUP(V8,名簿!A:L,3,FALSE) -> 技術製造部 | X8: =VLOOKUP(V8,名簿!A:L,4,FALSE) -> 生産管理課 | Y8: =VLOOKUP(V8,名簿!A:L,5,FALSE) -> 生産管理事務 | Z8: =VLOOKUP(V8,名簿!A:L,11,FALSE) -> 本社 | AA8: =VLOOKUP(V8,名簿!A:L,12,FALSE) -> 3F/シンク前
A9: 3 | B9: 45746 | H9: 1 | I9: 1 | R9: ・定期的にデスクトップのアイコン位置シャッフルされる | V9: 徳永彩花 | W9: =VLOOKUP(V9,名簿!A:L,3,FALSE) -> 技術製造部 | X9: =VLOOKUP(V9,名簿!A:L,4,FALSE) -> 生産管理課 | Y9: =VLOOKUP(V9,名簿!A:L,5,FALSE) -> 生産管理事務 | Z9: =VLOOKUP(V9,名簿!A:L,11,FALSE) -> 本社 | AA9: =VLOOKUP(V9,名簿!A:L,12,FALSE) -> 3F/シンク前
A10: 4 | B10: 45746 | G10: ハイパーリンク | H10: 1 | I10: 1 | J10: 1 | R10: ・たまにハイパーリンクが死亡する(どういった場合かは不明。突然発生する) | V10: 東香里 | W10: =VLOOKUP(V10,名簿!A:L,3,FALSE) -> 技術製造部 | X10: =VLOOKUP(V10,名簿!A:L,4,FALSE) -> 生産管理課 | Y10: =VLOOKUP(V10,名簿!A:L,5,FALSE) -> 生産管理事務 | Z10: =VLOOKUP(V10,名簿!A:L,11,FALSE) -> 本社 | AA10: =VLOOKUP(V10,名簿!A:L,12,FALSE) -> 3F/シンク前
A11: 5 | B11: 45746 | G11: PDF | H11: 1 | I11: 1 | J11: 1 | R11: ・PDFの文字化け(最近落ち着いた気がしますが…) | V11: 東香里 | W11: =VLOOKUP(V11,名簿!A:L,3,FALSE) -> 技術製造部 | X11: =VLOOKUP(V11,名簿!A:L,4,FALSE) -> 生産管理課 | Y11: =VLOOKUP(V11,名簿!A:L,5,FALSE) -> 生産管理事務 | Z11: =VLOOKUP(V11,名簿!A:L,11,FALSE) -> 本社 | AA11: =VLOOKUP(V11,名簿!A:L,12,FALSE) -> 3F/シンク前
A12: 6 | B12: 45746 | G12: PDF | H12: 1 | I12: 1 | J12: 1 | R12: ・概ねPDFが重い気がします | V12: 東香里 | W12: =VLOOKUP(V12,名簿!A:L,3,FALSE) -> 技術製造部 | X12: =VLOOKUP(V12,名簿!A:L,4,FALSE) -> 生産管理課 | Y12: =VLOOKUP(V12,名簿!A:L,5,FALSE) -> 生産管理事務 | Z12: =VLOOKUP(V12,名簿!A:L,11,FALSE) -> 本社 | AA12: =VLOOKUP(V12,名簿!A:L,12,FALSE) -> 3F/シンク前
A13: 7 | B13: 45746 | H13: 1 | I13: 1 | R13: ・天気が悪いとPCの動きが鈍い | V13: 東香里 | W13: =VLOOKUP(V13,名簿!A:L,3,FALSE) -> 技術製造部 | X13: =VLOOKUP(V13,名簿!A:L,4,FALSE) -> 生産管理課 | Y13: =VLOOKUP(V13,名簿!A:L,5,FALSE) -> 生産管理事務 | Z13: =VLOOKUP(V13,名簿!A:L,11,FALSE) -> 本社 | AA13: =VLOOKUP(V13,名簿!A:L,12,FALSE) -> 3F/シンク前
A14: 8 | B14: 45746 | K14: 1 | R14: ・受注時に「クライアント名」「製品名」に読み仮名をつけるようにして欲しい。様々の物をフォルダ分けする際に名前が不明な事が多く困る為。 | V14: 徳永彩花 | W14: =VLOOKUP(V14,名簿!A:L,3,FALSE) -> 技術製造部 | X14: =VLOOKUP(V14,名簿!A:L,4,FALSE) -> 生産管理課 | Y14: =VLOOKUP(V14,名簿!A:L,5,FALSE) -> 生産管理事務 | Z14: =VLOOKUP(V14,名簿!A:L,11,FALSE) -> 本社 | AA14: =VLOOKUP(V14,名簿!A:L,12,FALSE) -> 3F/シンク前
A15: 9 | B15: 45746 | K15: 1 | R15: ・受注時に「クライアント名」「製品名」に読み仮名をつけるようにして欲しい。様々の物をフォルダ分けする際に名前が不明な事が多く困る為。 | V15: 東香里 | W15: =VLOOKUP(V15,名簿!A:L,3,FALSE) -> 技術製造部 | X15: =VLOOKUP(V15,名簿!A:L,4,FALSE) -> 生産管理課 | Y15: =VLOOKUP(V15,名簿!A:L,5,FALSE) -> 生産管理事務 | Z15: =VLOOKUP(V15,名簿!A:L,11,FALSE) -> 本社 | AA15: =VLOOKUP(V15,名簿!A:L,12,FALSE) -> 3F/シンク前
A16: 10 | B16: 45746 | H16: 1 | I16: 1 | R16: ・ローカル、サーバー共にフリーズが多い | V16: 中島和哉 | W16: =VLOOKUP(V16,名簿!A:L,3,FALSE) -> 技術製造部 | X16: =VLOOKUP(V16,名簿!A:L,4,FALSE) -> 生産管理課 | Y16: =VLOOKUP(V16,名簿!A:L,5,FALSE) -> 生産管理 | Z16: =VLOOKUP(V16,名簿!A:L,11,FALSE) -> 本社 | AA16: =VLOOKUP(V16,名簿!A:L,12,FALSE) -> 3F/シンク前
A17: 11 | B17: 45746 | H17: 1 | I17: 1 | R17: ・パソコンの起動が遅く、シンクラの接続にも時間が掛かる、電源入～デスクトップの画面表示まで約3分30秒、Aサーバー接続アイコン選択～シンクラ画面まで約2分30秒 | V17: 中島和哉 | W17: =VLOOKUP(V17,名簿!A:L,3,FALSE) -> 技術製造部 | X17: =VLOOKUP(V17,名簿!A:L,4,FALSE) -> 生産管理課 | Y17: =VLOOKUP(V17,名簿!A:L,5,FALSE) -> 生産管理 | Z17: =VLOOKUP(V17,名簿!A:L,11,FALSE) -> 本社 | AA17: =VLOOKUP(V17,名簿!A:L,12,FALSE) -> 3F/シンク前
A18: 12 | B18: 45746 | H18: 1 | I18: 1 | J18: 1 | R18: ・ローカルのブラウザやSkypeの起動が遅い(1～3分くらい掛かる) | V18: 中島和哉 | W18: =VLOOKUP(V18,名簿!A:L,3,FALSE) -> 技術製造部 | X18: =VLOOKUP(V18,名簿!A:L,4,FALSE) -> 生産管理課 | Y18: =VLOOKUP(V18,名簿!A:L,5,FALSE) -> 生産管理 | Z18: =VLOOKUP(V18,名簿!A:L,11,FALSE) -> 本社 | AA18: =VLOOKUP(V18,名簿!A:L,12,FALSE) -> 3F/シンク前
A19: 13 | B19: 45746 | G19: デュアルモニター | H19: 1 | K19: 1 | O19: 1 | R19: ・複数のデータを見ながら処理を進めることが多いので、デュアルモニターだと作業効率が上がりそうです | V19: 中島和哉 | W19: =VLOOKUP(V19,名簿!A:L,3,FALSE) -> 技術製造部 | X19: =VLOOKUP(V19,名簿!A:L,4,FALSE) -> 生産管理課 | Y19: =VLOOKUP(V19,名簿!A:L,5,FALSE) -> 生産管理 | Z19: =VLOOKUP(V19,名簿!A:L,11,FALSE) -> 本社 | AA19: =VLOOKUP(V19,名簿!A:L,12,FALSE) -> 3F/シンク前
A20: 14 | B20: 45746 | H20: 1 | I20: 1 | R20: ・Bサーバー基本的に重い | V20: 池田悦彰 | W20: =VLOOKUP(V20,名簿!A:L,3,FALSE) -> 技術製造部 | X20: =VLOOKUP(V20,名簿!A:L,4,FALSE) -> 生産管理課 | Y20: =VLOOKUP(V20,名簿!A:L,5,FALSE) -> 物流 | Z20: =VLOOKUP(V20,名簿!A:L,11,FALSE) -> 第一倉庫 | AA20: =VLOOKUP(V20,名簿!A:L,12,FALSE) -> 1F/南西角
A21: 15 | B21: 45746 | G21: ハンディターミナル | H21: 1 | I21: 1 | K21: 1 | R21: ・ハンディの動作反応が年々遅くなっている→データ蓄積されているため？ | V21: 池田悦彰 | W21: =VLOOKUP(V21,名簿!A:L,3,FALSE) -> 技術製造部 | X21: =VLOOKUP(V21,名簿!A:L,4,FALSE) -> 生産管理課 | Y21: =VLOOKUP(V21,名簿!A:L,5,FALSE) -> 物流 | Z21: =VLOOKUP(V21,名簿!A:L,11,FALSE) -> 第一倉庫 | AA21: =VLOOKUP(V21,名簿!A:L,12,FALSE) -> 1F/南西角
A22: 16 | B22: 45746 | G22: メール検索 | I22: 1 | J22: 1 | R22: ・メールの検索がしにくく困ってます。これはOutlookだからなのか、Gmailだと変わるのはわかりません。 | V22: 馬場阿弥子 | W22: =VLOOKUP(V22,名簿!A:L,3,FALSE) -> 技術製造部 | X22: =VLOOKUP(V22,名簿!A:L,4,FALSE) -> 生産管理課 | Y22: =VLOOKUP(V22,名簿!A:L,5,FALSE) -> 生産管理 | Z22: =VLOOKUP(V22,名簿!A:L,11,FALSE) -> 本社 | AA22: =VLOOKUP(V22,名簿!A:L,12,FALSE) -> 3F/シンク前
A23: 17 | B23: 45746 | G23: ハイパーリンク | H23: 1 | I23: 1 | J23: 1 | R23: ・エクセルのハイパーリンクはバグりやすいです | V23: 馬場阿弥子 | W23: =VLOOKUP(V23,名簿!A:L,3,FALSE) -> 技術製造部 | X23: =VLOOKUP(V23,名簿!A:L,4,FALSE) -> 生産管理課 | Y23: =VLOOKUP(V23,名簿!A:L,5,FALSE) -> 生産管理 | Z23: =VLOOKUP(V23,名簿!A:L,11,FALSE) -> 本社 | AA23: =VLOOKUP(V23,名簿!A:L,12,FALSE) -> 3F/シンク前
A24: 18 | B24: 45746 | G24: デュアルモニター | H24: 1 | K24: 1 | O24: 1 | R24: ・デュアルモニターの対応ができてデータを並べられたら、効率は上がる可能性あります。 例えば、製造予定とTPCIS等を並べて確認や、充填バルクの製造予定並べて見れたら、画面が広分確認はしやすいです。 | V24: 馬場阿弥子 | W24: =VLOOKUP(V24,名簿!A:L,3,FALSE) -> 技術製造部 | X24: =VLOOKUP(V24,名簿!A:L,4,FALSE) -> 生産管理課 | Y24: =VLOOKUP(V24,名簿!A:L,5,FALSE) -> 生産管理 | Z24: =VLOOKUP(V24,名簿!A:L,11,FALSE) -> 本社 | AA24: =VLOOKUP(V24,名簿!A:L,12,FALSE) -> 3F/シンク前
A25: 19 | B25: 45746 | H25: 1 | I25: 1 | R25: ・サーバーのフリーズが多い | V25: 馬場阿弥子 | W25: =VLOOKUP(V25,名簿!A:L,3,FALSE) -> 技術製造部 | X25: =VLOOKUP(V25,名簿!A:L,4,FALSE) -> 生産管理課 | Y25: =VLOOKUP(V25,名簿!A:L,5,FALSE) -> 生産管理 | Z25: =VLOOKUP(V25,名簿!A:L,11,FALSE) -> 本社 | AA25: =VLOOKUP(V25,名簿!A:L,12,FALSE) -> 3F/シンク前
A26: 20 | B26: 45746 | H26: 1 | I26: 1 | J26: 1 | R26: ・Rグループが重いのとSkypeも終わるタイミングで、チャットやweb会議、スケジュール管理を、 Microsoft系かGoogle系にまとめられたら、各自予定の登録や確認がしやすいかなと思います。 | V26: 馬場阿弥子 | W26: =VLOOKUP(V26,名簿!A:L,3,FALSE) -> 技術製造部 | X26: =VLOOKUP(V26,名簿!A:L,4,FALSE) -> 生産管理課 | Y26: =VLOOKUP(V26,名簿!A:L,5,FALSE) -> 生産管理 | Z26: =VLOOKUP(V26,名簿!A:L,11,FALSE) -> 本社 | AA26: =VLOOKUP(V26,名簿!A:L,12,FALSE) -> 3F/シンク前
A27: 21 | B27: 45746 | G27: メール検索 | I27: 1 | J27: 1 | R27: ・メールの検索がしにくく困る。 | V27: 島田智章 | W27: =VLOOKUP(V27,名簿!A:L,3,FALSE) -> 技術製造部 | X27: =VLOOKUP(V27,名簿!A:L,4,FALSE) -> 生産管理課 | Y27: =VLOOKUP(V27,名簿!A:L,5,FALSE) -> 生産管理 | Z27: =VLOOKUP(V27,名簿!A:L,11,FALSE) -> 本社 | AA27: =VLOOKUP(V27,名簿!A:L,12,FALSE) -> 3F/シンク前
A28: 22 | B28: 45746 | H28: 1 | I28: 1 | R28: ・ローカルのブラウザやSkypeの起動が遅い(1～3分くらい掛かる) | V28: 島田智章 | W28: =VLOOKUP(V28,名簿!A:L,3,FALSE) -> 技術製造部 | X28: =VLOOKUP(V28,名簿!A:L,4,FALSE) -> 生産管理課 | Y28: =VLOOKUP(V28,名簿!A:L,5,FALSE) -> 生産管理 | Z28: =VLOOKUP(V28,名簿!A:L,11,FALSE) -> 本社 | AA28: =VLOOKUP(V28,名簿!A:L,12,FALSE) -> 3F/シンク前
A29: 23 | B29: 45746 | H29: 1 | I29: 1 | R29: ・パソコンの起動が遅く、シンクラの接続にも時間が掛かる(中島くんと同等の所要時間) ※島田主任と中島くんのPCスペックは同等です | V29: 島田智章 | W29: =VLOOKUP(V29,名簿!A:L,3,FALSE) -> 技術製造部 | X29: =VLOOKUP(V29,名簿!A:L,4,FALSE) -> 生産管理課 | Y29: =VLOOKUP(V29,名簿!A:L,5,FALSE) -> 生産管理 | Z29: =VLOOKUP(V29,名簿!A:L,11,FALSE) -> 本社 | AA29: =VLOOKUP(V29,名簿!A:L,12,FALSE) -> 3F/シンク前
A30: 24 | B30: 45746 | G30: メール振分 | I30: 1 | J30: 1 | R30: ・メーリングリストで受信したbouncesのせい？でメールの振り分けが僕には対応できなくなってます。 | V30: 島田智章 | W30: =VLOOKUP(V30,名簿!A:L,3,FALSE) -> 技術製造部 | X30: =VLOOKUP(V30,名簿!A:L,4,FALSE) -> 生産管理課 | Y30: =VLOOKUP(V30,名簿!A:L,5,FALSE) -> 生産管理 | Z30: =VLOOKUP(V30,名簿!A:L,11,FALSE) -> 本社 | AA30: =VLOOKUP(V30,名簿!A:L,12,FALSE) -> 3F/シンク前
A31: 25 | B31: 45746 | H31: 1 | I31: 1 | R31: ・シンクラサーバーの動作が全体的に重い。（シンクラが原因なのか、PC自体が古いからなのかは分からないです） | V31: 北村優樹 | W31: =VLOOKUP(V31,名簿!A:L,3,FALSE) -> 技術製造部 | X31: =VLOOKUP(V31,名簿!A:L,4,FALSE) -> 生産管理課 | Y31: =VLOOKUP(V31,名簿!A:L,5,FALSE) -> 物流 | Z31: =VLOOKUP(V31,名簿!A:L,11,FALSE) -> コスメファクトリー | AA31: =VLOOKUP(V31,名簿!A:L,12,FALSE) -> 1F/事務所
A32: 26 | B32: 45746 | H32: 1 | I32: 1 | R32: ・フリーズが頻発する。社員のパソコン使用が集中する時間帯（主に9時頃、18時頃）は特に多く、長くフリーズする。 | V32: 北村優樹 | W32: =VLOOKUP(V32,名簿!A:L,3,FALSE) -> 技術製造部 | X32: =VLOOKUP(V32,名簿!A:L,4,FALSE) -> 生産管理課 | Y32: =VLOOKUP(V32,名簿!A:L,5,FALSE) -> 物流 | Z32: =VLOOKUP(V32,名簿!A:L,11,FALSE) -> コスメファクトリー | AA32: =VLOOKUP(V32,名簿!A:L,12,FALSE) -> 1F/事務所
A33: 27 | B33: 45746 | H33: 1 | I33: 1 | R33: ・サーバーにつながりにくい（特に朝９時ぐらい） | V33: 小田晶彦 | W33: =VLOOKUP(V33,名簿!A:L,3,FALSE) -> 技術製造部 | X33: =VLOOKUP(V33,名簿!A:L,4,FALSE) -> 製造課 | Y33: =VLOOKUP(V33,名簿!A:L,5,FALSE) -> バルク・顆粒 | Z33: =VLOOKUP(V33,名簿!A:L,11,FALSE) -> コスメラボラトリー | AA33: =VLOOKUP(V33,名簿!A:L,12,FALSE) -> 2F/事務所
A34: 28 | B34: 45746 | G34: 現品票発行 | H34: 1 | I34: 1 | J34: 1 | K34: 1 | R34: ・ネットの環境か分からないが、現品票の発行（印刷）に時間がかかる。 | V34: 小田晶彦 | W34: =VLOOKUP(V34,名簿!A:L,3,FALSE) -> 技術製造部 | X34: =VLOOKUP(V34,名簿!A:L,4,FALSE) -> 製造課 | Y34: =VLOOKUP(V34,名簿!A:L,5,FALSE) -> バルク・顆粒 | Z34: =VLOOKUP(V34,名簿!A:L,11,FALSE) -> コスメラボラトリー | AA34: =VLOOKUP(V34,名簿!A:L,12,FALSE) -> 2F/事務所
A35: 29 | B35: 45746 | D35: 46098 | G35: TPiCS・PI-navi | H35: 1 | I35: 1 | J35: 1 | R35: ・朝の９時以外でもメールやTPiCS・PI-naviが遅い時がある。時間は見てないです。あきらめて製造に戻る時もあります。 | S35: 鳥山 | T35: 3/17PI-navi完了操作遅滞-TA調査依頼 3/18最大限チューニング済 | V35: 小田晶彦 | W35: =VLOOKUP(V35,名簿!A:L,3,FALSE) -> 技術製造部 | X35: =VLOOKUP(V35,名簿!A:L,4,FALSE) -> 製造課 | Y35: =VLOOKUP(V35,名簿!A:L,5,FALSE) -> バルク・顆粒 | Z35: =VLOOKUP(V35,名簿!A:L,11,FALSE) -> コスメラボラトリー | AA35: =VLOOKUP(V35,名簿!A:L,12,FALSE) -> 2F/事務所
A36: 30 | B36: 45746 | H36: 1 | I36: 1 | R36: ・要望はパソコンはスムーズに使いたい。 製造してる合間に打ち込んだりメール見ることがあるので、ネットがつながらないとかあると、作業効率が悪いです。 | V36: 小田晶彦 | W36: =VLOOKUP(V36,名簿!A:L,3,FALSE) -> 技術製造部 | X36: =VLOOKUP(V36,名簿!A:L,4,FALSE) -> 製造課 | Y36: =VLOOKUP(V36,名簿!A:L,5,FALSE) -> バルク・顆粒 | Z36: =VLOOKUP(V36,名簿!A:L,11,FALSE) -> コスメラボラトリー | AA36: =VLOOKUP(V36,名簿!A:L,12,FALSE) -> 2F/事務所
A37: 31 | B37: 45746 | H37: 1 | I37: 1 | R37: 私的には以前に容量削減の対策をやってからフリーズすることがかなり改善したように思います。ただ大川リーダー、伊澤Ｌは今でも動作が重たくなる時はあるとのことです。 | V37: 内藤恭介 | W37: =VLOOKUP(V37,名簿!A:L,3,FALSE) -> 技術製造部 | X37: =VLOOKUP(V37,名簿!A:L,4,FALSE) -> 製造課 | Y37: =VLOOKUP(V37,名簿!A:L,5,FALSE) -> 粉体 | Z37: =VLOOKUP(V37,名簿!A:L,11,FALSE) -> 本社 | AA37: =VLOOKUP(V37,名簿!A:L,12,FALSE) -> 3F/シンク前
A38: 32 | B38: 45746 | G38: 共有フォルダ | K38: 1 | P38: 4 | R38: 製造フォルダの中はかなりフォルダ数多く複雑です。「製造用」とか「元製造」とか「製造用１」がありあまり分別もできていないと思います。探すのが大変なので自分の必要なものはショートカットを作成しまとめていますが大昔のデータも多く処分していいかわからないので皆さん放置状態になっているのかと思います。 | S38: 中村 | T38: 3/11～構造可視化ツール/検索ツール/データコピーツール作成中 3/23完成 | V38: 内藤恭介 | W38: =VLOOKUP(V38,名簿!A:L,3,FALSE) -> 技術製造部 | X38: =VLOOKUP(V38,名簿!A:L,4,FALSE) -> 製造課 | Y38: =VLOOKUP(V38,名簿!A:L,5,FALSE) -> 粉体 | Z38: =VLOOKUP(V38,名簿!A:L,11,FALSE) -> 本社 | AA38: =VLOOKUP(V38,名簿!A:L,12,FALSE) -> 3F/シンク前
A39: 33 | B39: 45746 | G39: 時間帯 | H39: 1 | I39: 1 | R39: サーバーの動作が遅く、すぐ切断される。開発、BeGardenの出勤時刻9時頃が最もサーバーにつながりにくい。 | V39: 小田勇雄 | W39: =VLOOKUP(V39,名簿!A:L,3,FALSE) -> 技術製造部 | X39: =VLOOKUP(V39,名簿!A:L,4,FALSE) -> 製造課 | Y39: =VLOOKUP(V39,名簿!A:L,5,FALSE) -> 充填包装 | Z39: =VLOOKUP(V39,名簿!A:L,11,FALSE) -> コスメラボラトリー | AA39: =VLOOKUP(V39,名簿!A:L,12,FALSE) -> 2F/事務所
A40: 34 | B40: 45746 | G40: Wi-Fi設定 | I40: 1 | R40: 移動していないのにWi-fiが途切れ、他のWi-fiにつながってしまう。 | V40: 小田勇雄 | W40: =VLOOKUP(V40,名簿!A:L,3,FALSE) -> 技術製造部 | X40: =VLOOKUP(V40,名簿!A:L,4,FALSE) -> 製造課 | Y40: =VLOOKUP(V40,名簿!A:L,5,FALSE) -> 充填包装 | Z40: =VLOOKUP(V40,名簿!A:L,11,FALSE) -> コスメラボラトリー | AA40: =VLOOKUP(V40,名簿!A:L,12,FALSE) -> 2F/事務所
...

Sheet 🔑
F1: Q5.AI・ツール活用 未回答者
K2: 部 | L2: 課 | M2: 係 | N2: 氏名 | O2: 候補者
A3: 氏名 | B3: 部 | C3: 課 | D3: 係 | F3: 部 | G3: 課 | H3: 係 | I3: 個数 / 氏名 | K3: 研究開発部 | L3: 研究開発課 | M3: - | N3: 山下基宏 | O3: 5
A4: 大前道仁 | B4: =VLOOKUP(A4,名簿!A:E,3,FALSE) -> EC事業部 | C4: =VLOOKUP(A4,名簿!A:E,4,FALSE) -> EC事業課 | D4: =VLOOKUP(A4,名簿!A:E,5,FALSE) -> - | F4: 研究開発部 | G4: 研究開発課 | H4: - | I4: 6 | N4: 宗近倶枝 | O4: 5
A5: 小田勇雄 | B5: =VLOOKUP(A5,名簿!A:E,3,FALSE) -> 技術製造部 | C5: =VLOOKUP(A5,名簿!A:E,4,FALSE) -> 製造課 | D5: =VLOOKUP(A5,名簿!A:E,5,FALSE) -> 充填包装 | F5: 品質保証部 | G5: 品質管理課 | H5: - | I5: 1 | O5: 4
A6: 北村優樹 | B6: =VLOOKUP(A6,名簿!A:E,3,FALSE) -> 技術製造部 | C6: =VLOOKUP(A6,名簿!A:E,4,FALSE) -> 生産管理課 | D6: =VLOOKUP(A6,名簿!A:E,5,FALSE) -> 物流 | F6: 技術製造部 | G6: 生産管理課 | H6: 物流 | I6: 2 | N6: 津田宝加 | O6: 4
A7: 近藤雅人 | B7: =VLOOKUP(A7,名簿!A:E,3,FALSE) -> 研究開発部 | C7: =VLOOKUP(A7,名簿!A:E,4,FALSE) -> 研究開発課 | D7: =VLOOKUP(A7,名簿!A:E,5,FALSE) -> - | G7: 製造課 | H7: 充填包装 | I7: 5 | K7: 品質保証部 | L7: 品質管理課 | M7: - | N7: 野村秀太朗 | O7: 4
A8: 田中裕一 | B8: =VLOOKUP(A8,名簿!A:E,3,FALSE) -> 技術製造部 | C8: =VLOOKUP(A8,名簿!A:E,4,FALSE) -> 製造課 | D8: =VLOOKUP(A8,名簿!A:E,5,FALSE) -> 充填包装 | H8: バルク・顆粒 | I8: 1 | K8: EC事業部 | L8: EC事業課 | M8: - | N8: 大前道仁 | O8: 5
A9: 津田宝加 | B9: =VLOOKUP(A9,名簿!A:E,3,FALSE) -> 研究開発部 | C9: =VLOOKUP(A9,名簿!A:E,4,FALSE) -> 研究開発課 | D9: =VLOOKUP(A9,名簿!A:E,5,FALSE) -> - | F9: 企画営業部 | G9: 企画課 | H9: - | I9: 2 | K9: 技術製造部 | L9: - | M9: - | N9: 森山貴史 | O9: 5
A10: 堂山利奈 | B10: =VLOOKUP(A10,名簿!A:E,3,FALSE) -> 企画営業部 | C10: =VLOOKUP(A10,名簿!A:E,4,FALSE) -> 企画課 | D10: =VLOOKUP(A10,名簿!A:E,5,FALSE) -> - | F10: EC事業部 | G10: EC事業課 | H10: - | I10: 1 | L10: 生産管理課 | M10: 生産管理 | N10: 島田智章 | O10: 4
A11: 直木美佐子 | B11: =VLOOKUP(A11,名簿!A:E,3,FALSE) -> 研究開発部 | C11: =VLOOKUP(A11,名簿!A:E,4,FALSE) -> 研究開発課 | D11: =VLOOKUP(A11,名簿!A:E,5,FALSE) -> - | F11: 総計 | I11: 18 | N11: 馬場阿弥子 | O11: 5
A12: 西村穂乃果 | B12: =VLOOKUP(A12,名簿!A:E,3,FALSE) -> 品質保証部 | C12: =VLOOKUP(A12,名簿!A:E,4,FALSE) -> 品質管理課 | D12: =VLOOKUP(A12,名簿!A:E,5,FALSE) -> - | M12: 生産管理事務 | N12: 東香里 | O12: 4
A13: 橋口千聖 | B13: =VLOOKUP(A13,名簿!A:E,3,FALSE) -> 研究開発部 | C13: =VLOOKUP(A13,名簿!A:E,4,FALSE) -> 研究開発課 | D13: =VLOOKUP(A13,名簿!A:E,5,FALSE) -> - | M13: 物流 | N13: 池田悦彰 | O13: 5
A14: 濱西藍伽 | B14: =VLOOKUP(A14,名簿!A:E,3,FALSE) -> 企画営業部 | C14: =VLOOKUP(A14,名簿!A:E,4,FALSE) -> 企画課 | D14: =VLOOKUP(A14,名簿!A:E,5,FALSE) -> - | O14: 4
A15: 藤本洸平 | B15: =VLOOKUP(A15,名簿!A:E,3,FALSE) -> 技術製造部 | C15: =VLOOKUP(A15,名簿!A:E,4,FALSE) -> 製造課 | D15: =VLOOKUP(A15,名簿!A:E,5,FALSE) -> 充填包装 | L15: 製造課 | M15: バルク・顆粒 | N15: 外間裕貴人 | O15: 5
A16: 松山丈弘 | B16: =VLOOKUP(A16,名簿!A:E,3,FALSE) -> 技術製造部 | C16: =VLOOKUP(A16,名簿!A:E,4,FALSE) -> 製造課 | D16: =VLOOKUP(A16,名簿!A:E,5,FALSE) -> 充填包装 | M16: 液体 | N16: 大川泰弘 | O16: 4
A17: 森尾直浩 | B17: =VLOOKUP(A17,名簿!A:E,3,FALSE) -> 技術製造部 | C17: =VLOOKUP(A17,名簿!A:E,4,FALSE) -> 生産管理課 | D17: =VLOOKUP(A17,名簿!A:E,5,FALSE) -> 物流 | M17: 充填包装 | N17: 東口智一 | O17: 5
A18: 矢野恵 | B18: =VLOOKUP(A18,名簿!A:E,3,FALSE) -> 研究開発部 | C18: =VLOOKUP(A18,名簿!A:E,4,FALSE) -> 研究開発課 | D18: =VLOOKUP(A18,名簿!A:E,5,FALSE) -> - | O18: 4
A19: 山下基宏 | B19: =VLOOKUP(A19,名簿!A:E,3,FALSE) -> 研究開発部 | C19: =VLOOKUP(A19,名簿!A:E,4,FALSE) -> 研究開発課 | D19: =VLOOKUP(A19,名簿!A:E,5,FALSE) -> - | M19: 粉体 | N19: 阿部俊樹 | O19: 5
A20: 吉山勝宏 | B20: =VLOOKUP(A20,名簿!A:E,3,FALSE) -> 技術製造部 | C20: =VLOOKUP(A20,名簿!A:E,4,FALSE) -> 製造課 | D20: =VLOOKUP(A20,名簿!A:E,5,FALSE) -> バルク・顆粒 | N20: 内藤恭介 | O20: 4
A21: 小柏拓海 | B21: =VLOOKUP(A21,名簿!A:E,3,FALSE) -> 技術製造部 | C21: =VLOOKUP(A21,名簿!A:E,4,FALSE) -> 製造課 | D21: =VLOOKUP(A21,名簿!A:E,5,FALSE) -> 充填包装 | K21: 管理部 | L21: 管理課 | M21: - | N21: 越智絵美子 | O21: 5
N22: 図書杏子 | O22: 4
K23: 企画営業部 | L23: - | M23: - | N23: 南光彦 | O23: 4
L24: 営業課 | M24: - | N24: 橋本悠司 | O24: 5
N25: 中村剛 | O25: 5
L26: 企画課 | M26: - | N26: 杉尾瑞樹 | O26: 4
K27: 総計

Sheet L
C1: 45838 | G1: 45838 | K1: 45863 | P1: 46073
A3: 期間 | C3: ↓収集した結果から増減 | E3: ヒアリングの視点 | J3: ① | K3: データ管理 | L3: 0 | M3: 無回答・無関心 | O3: 1 | P3: 全く思わない
A4: 短期 | C4: 区分 | E4: 初級 | F4: 実は基本を知らない、知識がないから分からない | J4: ② | K4: 仕組み・ルール | L4: 1 | M4: 気になる | O4: 2 | P4: あまり思わない
A5: 中期 | E5: ↓ | F5: 必ず覚えないといけないこと、今管理者に頼り切りにしていること＝自分で理解できていないこと | J5: ③ | K5: MS365 | L5: 2 | M5: 前向き | O5: 3 | P5: どちらともいえない
A6: 長期 | C6: IT基礎知識 | E6: ↓ | F6: 今の日々の業務で、もっと便利になったら嬉しいこと、変更されると不安なこと | J6: ④ | K6: セキュリティ | O6: 4 | P6: まあまあ思う
C7: 共有フォルダ | E7: 中級 | F7: 具体的な機能/ツールに対して、知りたいこと/活用方法 | J7: ⑤ | K7: ITスキル向上 | O7: 5 | P7: とても思う
C8: MS365(基礎) | J8: ⑥ | K8: その他
C9: MS365(活用)
C10: セキュリティ | F10: ヒアリング イメージ： 今 認識していること →わかりやすい不明点・問題点 →何が起きる？何が必要になる？
H11: ↓後から区分
F12: 初級 | G12: 何も分からないので、何を覚える必要があるのか分からない サーバが重いのは困る、そうならないように個人で守るルールがある？ | H12: IT基礎知識
F13: ↓ | G13: 先ず、今の環境の基礎用語/基本事項から順々に教えてほしい ローカル？サーバ？ 繋がらない・重くなる理由 良いこと・悪いこと | H13: IT基礎知識
F14: 中級 | G14: なぜシンクライアントサーバを使っているのか？ サーバが撤廃されるとどうなるのか？ それぞれの長所・短所 | H14: IT基礎知識
F16: 初級 | G16: 共有フォルダの無駄や重複を減らして、保存・管理する方法 | H16: 共有フォルダ
F17: ↓ | G17: 最初は管理できていても、業務体制が変わったり期間が経つとフォルダの規則性が無くなっていく 長期で維持できるようにするには？ | H17: 共有フォルダ
F18: 中級 | G18: 全部署/全社員が同じ意識やルールで保存したり管理できるようになる方法 上書き/消去/漏洩の回避 マスタデータの保全 | H18: 共有フォルダ
F20: 初級 | G20: 今のOfficeと何が違うのか？ 何が便利になるのか？ 使い方も変わるのか？ | H20: MS365(基礎)
F21: ↓ | G21: クラウドストレージとは？ コミュニティツールとは？ 今のファイルはどうなるのか？ サーバとの違い 便利になること、難しいこと | H21: MS365(基礎)
F22: 中級 | G22: サーバとローカルでどう使う/動作するのか？ ファイル共有・クラウドバックアップとして使う方法 | H22: MS365(基礎)
F24: 初級 | G24: 迷惑メール以外に気をつけること | H24: セキュリティ
F25: ↓ | G25: 具体的にどんな危険があって、どうやって対策するもの？ やってはいけないことは？ | H25: セキュリティ
F26: 中級 | G26: 今 動いているセキュリティ対策は？ 接続できない時はどうすればよいのか？ 個人の誤操作で会社全体に及ぶ危険性とは？ | H26: セキュリティ

Sheet 260220
A1: タイムスタンプ | B1: 部署 | C1: 氏名 | D1: Q1.毎回「ちょっと面倒だな…」と感じる作業はありますか？ 具体的な業務内容やファイル名があれば教えてください （例：毎週の集計作業、同じ内容の繰り返し入力 など） | E1: Q2.ミスが起こりやすい、またはチェックに時間がかかる作業はありますか？ 具体的な業務内容やファイル名があれば教えてください （例：転記作業、数値の照合、複数ファイルの突合 など） | F1: Q3. 工数がかかりすぎている、改善したいと感じる作業はありますか？ 具体的な業務内容やファイル名があれば教えてください （例：手順が多い業務、データ集め、資料作成 など） | G1: Q4. 紙や手書きでやっているが、PC化できたら楽になりそうな作業はありますか？ （例：手書き帳票、紙の申請書、メモからの転記 など） | H1: Q5-1. AIや便利ツールを業務で使ってみたいと思いますか？ 1 = 全く思わない 2 = あまり思わない 3 = どちらともいえない 4 = まあまあ思う 5 = とても思う | I1: Q5-2.使用している(使ったことがある)AIがあれば、名称と用途を教えてください。 | J1: Q6. 業務改善のアイデアや要望があれば自由に記入してください
A2: 46066.558 | B2: 技術製造部 製造課（化粧品） | C2: 森山 貴史 | D2: パートさんの給与時間計算、社員同様にKING OF TIME化できれば負担軽減できる。 | F2: ISO22716取得後の書類作成が多すぎる。特に製造指図書 | G2: 製造指図書、製造記録表等々 包装工程は係長が常にPC入力しており作業負担のため間略化希望する。 | H2: 5 | I2: 溶融充填機設備仕様 冷却設備仕様について
A3: 46066.567 | B3: 技術製造部 生産管理課 | C3: 鳥山 一洋 | D3: ・日/週ルーティンのデータベースからの抽出/加工作業 手動作業が多く、日々時間がかかってしまうため、AIを用いて改善中 ・電話での原料の在庫/入荷/使用予定の問い合わせへの対応 ヒアリングの上、ツールを作成し改善を計画している | E3: ・入荷資材検品 支給資材などで、事前連絡なく微細な改版があるものなど 目視検査では見落としてしまうリスクがある | F3: ・日/週のルーティン作業 Q1の内容と同じです | G3: 自身の作業の中で、手書き業務で負荷の高いものはないため ここに該当する作業はございません | H3: 5 | I3: ・Genspark、ChatGPT どのようなことができるのか、試しに使った程度 ・Claude VBA、SQL、スクリプトなどの作成と修正に日常的に使用 | J3: 全員がAIに興味・関心を持ち、使用するような環境には恐らくならないと思われるが 社内で1名でも多くAIの使い方を知り、活用することで日常業務の細かなことでも 日々改善できるような環境ができれば良いと感じる
A4: 46066.576 | B4: 企画営業部 営業課 | C4: 南 光彦 | D4: クライアント毎のスケジュール表作成・概算コストの試算 | H4: 4
A5: 46066.584 | B5: 技術製造部 生産管理課 | C5: 馬場阿弥子 | D5: バルク・充填製造予定表の更新、定例会議の議事録 | E5: 充填製造予定表で島田主任に作成いただき、そのあと、変更箇所・資材納期状況確認し色付けするなどは、意外に時間をとるため少し手間です。 バルク製造予定表は、バルクの昔からの予定表で確認・転記して、充填日・検査合格日の記載とチェックは大切ですが手間ではあります。 | H5: 5 | J5: ・製品の出荷依頼済の内容を、日付順で受注番号別の一覧化で見れたらなと思います 製造が立て込んだ際やトラブルなどで、出荷依頼が出てるか現場から聞かれたり、 直近の予定変更の対応の場合でも、自分のタイミングで確認ができれば問い合わせも減り、 確認自体も手間が減るので助かります。 また、担当者も出荷依頼したかどうかの確認もしやすいと思います。 ・各製品の入数やパレット積載、納品時のルール、商品または得意先様毎の特記事項などを共有・管理できて、各自のタイミングで見れる場所があれば、担当者変更やトラブルがあっても、基本情報は確認しやすく周囲もフォローしやすいと思います。 新規の取引先・商品、納品先などの場合は、必要情報の登録などは発生しますが、それだけしておけば、毎回受注フォーマット記載も不要にできるのではと思います。 TPICSでできることもあると思いますが、各自のタイミングで確認できるのがポイントで、ログイン権限など気にせず、理想は社外にいてもできるといいなと思います。
A6: 46066.59 | B6: 技術製造部 生産管理課 | C6: 池田悦彰 | D6: アンファー資材の入荷日ごとの入荷記録と入出庫記録用紙の作成・ファイリング→生産管理課が出来る前からの作業。システムで大体把握できる気がするのでデータで管理したい | E6: アンファー製造予定変更時の化粧箱納期間に合っているかの確認 | H6: 5 | I6: ChatGPTでちょっとした疑問やエクセル操作など
A7: 46066.606 | B7: 企画営業部 営業課 | C7: 中村剛 | D7: 定期的な集計作業や、複数のExcel・CSVを扱う作業。 特に、同じ内容を複数ファイルへ入力・転記する工程が当てはまると思います。 | E7: 数値の転記や、複数ファイル間の数値照合作業。 手作業でのチェックが多く、集中力を要するため、負荷がかかっていると思います。 | F7: 定型フォーマットの報告資料作成や、データ収集から集計までの一連の作業。 手順が多く、改善余地があると感じます。 | G7: 経費申請 | H7: 5 | I7: ChatGPT ・画像生成 ・WEBやPythonのコードの改善 Ollama ・ローカル環境でのLLM実行 | J7: 小さな改善を積み重ねることで、現場の負担軽減と品質向上の両立ができると思います。 「少し楽になった」と実感できる事例が増えると、DXも自然に浸透していくと感じます。
A8: 46066.818 | B8: 技術製造部 製造課（食品添加物） | C8: 伊澤浩司 | D8: 経済産業省アルコール使用簿作成、グリセリンドレー手配作業、パソコン等電化製品処分、毎日のグリセリン在庫調べ、アルタン在庫報告、裏の駐輪場他の掃除、製造中の入出荷作業 | E8: 液体製品で別名が複数ある商品 | H8: 3
A9: 46069.722 | B9: 企画営業部 営業課 | C9: 橋本悠司 | D9: 案件依頼書の作成、案件見込共有、出荷判定取次、出荷連絡、契約書チェック | F9: 案件依頼書、案件見込管理、出荷判定取次フロー、出荷連絡フロー、契約書チェック | H9: 5 | I9: Copilot、Gemini、Canva、ChatGPT | J9: 外出や離席が多い業務は極力作業をスマホなどで出来るようにして業務効率を上げたい。 出荷連絡や出荷判定など営業を介さずに直接CLへ連絡する形にして、営業工数や連絡のタイムラグを少なくしたい。 クライアントに提出等が必要な書類関係はスマホからでも閲覧やダウンロードなど出来るようにしたい。 案件を一覧管理（受注、契約書、取り決め書、安定性試験、容器相性試験、支給原料依頼書など）して抜けや漏れを防げるようにしたい。
A10: 46069.727 | B10: 品質保証部 品質管理課 | C10: 井上 幸哉 | D10: 毎月の社員の体温を記録する用紙の作成 （ファイル名：健康管理①就業前検温測定記録 (00000003) 内容：基本的な色付けや社員名は自動化できているが、参照が上手く出来ない部分は手で行っている） 毎週、食添（粉体）の包材の個数をチェックし、必要な物は発注を行う。 （ファイル名：包材在庫管理表 内容：包材（ダンボール、袋、ラベル）の個数をチェックし、必要な物は発注を行う。） | E10: ミス：試験成績書の作成。数値の照合 チェックに時間がかかる：ロート製薬の出荷判定書の作成。転記作業 | F10: 包材管理。在庫がなければ製造ができないのに、在庫管理が全て人力に依存している。 管理品目の多さ。通年を通してマンパワー不足。管理名称と包材などの商品名がイコールではないことが、時間を削っている（工数がかかりすぎている）。 | G10: 包材に限らず、在庫管理にPC化が必要と思う。 できれば、エクセルで引き落としをして、在庫量を印刷 ⇒ 人がチェックして、実数と合わせる ⇒ 不足分は発注する。みたいな流れが取れるといいと思う。 メモからの転記はロートでよくしている。予定がわかっている分は、先に書類を出して欲しい。 | H10: 3 | I10: ない（携帯電話のSiriとか言葉での文字入力は含まれます？） | J10: AIを利用したことがないので、AIが分析をできるのかわからないですが、 食添は、分析値を残せば、安定・不安定な製剤が数値から見えてくる分野だと思います。 下記のエクセルファイルのようなことをしたくても、とっつきにくいようで、理解が得られないのが現状です。 （ファイル名：容器のキャビナンバーごとの重量測定と開栓トルク値の結果） 何とかしたいけど、お金もかけたくないし、情報が流出するリスクは避けたいです。
A11: 46070.369 | B11: 技術製造部 製造課（食品添加物） | C11: 内藤 恭介 | D11: 「月産製造結果表 2026年粉体」日毎と週間の毎月範囲指定する必要がある | E11: 受注商品（在庫品）のロット管理 同一商品を複数の客先に出し、受注順と納期順も異なる | F11: 特に思いつきません。 | G11: 打ち合わせのメモをジャンル毎で整理できれば便利かも。（衛生管理委員、製造会議等） | H11: 4 | I11: ｃｈａｔＧＰＴ | J11: 原料や資材の納期日が一覧で管理できれば便利かも。
A12: 46070.378 | B12: 企画営業部 企画課 | C12: 杉尾 瑞樹 | D12: 現状特にありません | E12: 現状特にありません | F12: 現状特にありません | H12: 4 | I12: chat GPT:調べた情報を文言をまとめるために使用、画像作成等 | J12: 特に今のところ問題なく業務に取り掛かれているかと思います。宜しくお願い致します。
A13: 46070.424 | B13: 技術製造部 生産管理課 | C13: 東香里 | D13: メールを送る際にどういったメーリスが存在し、どなたに配信されるのかいまだに不明です。メールアドレス一覧やメーリス配信先など閲覧しやすくなるとメールを送る際の時短になり送り漏れがなくなると感じます。 メールを送る際に送り先に悩む時間が発生する事がある為まずは一覧が欲しいです。 | E13: 武内製薬様など製品数が多い種類の在庫表の作業を行う際どうしても見落としが出てしまいます。 単純にファイルの問題というよりは製品全てが同じ在庫表の為(笑栄様などは案件毎に在庫表があります)、チェック項目が多くありミス自体は個人的な問題かと思います。ただ、在庫表の中で一番作業時間がかかる業務です。 | F13: 特にありません。 | G13: 特にありません。 | H13: 4 | I13: ChatGPT。無理なお願いをする際などメールの文章に困った際に参考にしていますが仕事上ではほぼ使わずほぼプライベートで使用しています。 | J13: どの部署にどなたがいるのか入れ替わりもありよくわからない為、所属部署・名前・メールアドレスなどが一覧で確認できるようになると助かるなと思います。他部署からこの人どなたですかと聞かれる事もある為、社員一覧(役職)もあると新しい人にも説明しやすいです。もしすでに存在するのであれば公に告知して欲しいです。
A14: 46070.434 | B14: 研究開発部 研究開発課 | C14: 宗近倶枝 | D14: バルク製造指図書の新規発行、原料在庫表と識別表の一元化できていない、バルクの概算原価（原料発注を開発でしなくなったため、生産管理に聞かないと解決できない場合がある） | E14: 案件依頼書は他案件からのコピペで作成していること等があり、案件を取り組む前に指図があっているかのやりとりをする工程が時々ある。案件依頼書は実務する方がやりやすいように改善検討してはどうかと考えます。 | F14: 特になし | G14: 議事録作成 | H14: 5 | I14: 特になし
A15: 46070.628 | B15: 品質保証部 品質管理課 | C15: 野村秀太朗 | D15: 化粧品用資材における検品用サンプルの抜取作業が、本社から第一倉庫まで移動せねばならず不便に感じています。 | E15: 納品予定資材と納品書の照合、資材ケースからの検品用サンプルの抜き取り作業 | F15: 予定資材の照合の際、急な予定変更が行われていると、その正否が確認できない。第一倉庫で抜き取りを行うが作業場が衛生的でないため汚れの混入が心配。 | G15: 納品予定資材と納品書の照合の際の予定表カレンダー。資材抜取の際には端末を使い最新データを確認できるようにしたい。 | H15: 4 | J15: 化粧品の検品用資材の抜取作業について、区画分けしたエリアで行ったほうがよいと思われます。開封した資材ケースにゴミが混入する可能性があります。そして物流担当者の事務作業スペースとあわせてフォークリフトの通り道にあるため接触事故が起こる危険があります。
A16: 46070.743 | B16: 技術製造部 製造課（化粧品） | C16: 外間 裕貴人 | F16: 〇グリセリンを使用するとき、ドラム原料のためエアーで充填できる治具を使用しているのですが、古くなっているせいか出てくる量があまりにも遅いです。多く量を使用するときなどとても時間がかかります。新しいものを購入するなどして改善したいです。 〇常温や冬などに気温が低い状態で保管していると固まる原料があります。使用するときに加温をして溶かさないといけないのですが、加温機に入れるか湯煎をするかで対応しています。現在使用している加温機が一斗缶を最大4缶までしか入れられず、それ以上溶かさないといけない原料がある場合に困っています。大きい加温機を購入するなど改善をしたいです。 〇原料を保管する冷蔵庫もいっぱいになってきており、新しい冷蔵庫を購入するなどして改善したいです。 | G16: 製造したバルクの現品票にメッシュの種類や香料の有無等の記載をするのですが、手書きで書いているものもあり10枚ほど現品票があるときは時間がかかりめんどくさく感じます。それぞれの製品ごとにデータ上で記入し保存したたうえで印刷出来ると楽になると思います。 | H16: 5
A17: 46070.785 | B17: 技術製造部 製造課（化粧品） | C17: 小田晶彦 | D17: ない | E17: 指図書等の書類の確認。 | F17: 無い | G17: 無い | H17: 2 | I17: 無い
A18: 46070.792 | B18: 技術製造部 生産管理課 | C18: 徳永彩花 | D18: 奉行クラウド使用者が生産管理内で4人いるがアカウント数が2しかない。後者が乗っ取り出来るので使用と終了の共有をしているが手間であり、急ぎ発注の時や他人の使用を妨げそうで不便 | E18: 原料発注において堂島実業様納品分を記録する直送予定一覧エクセルの更新漏れが起きやすい。 週1～2回TPiCSとエクセルを参照して変更漏れがないか確認はしているが発注済みの納期変更や数量変更が多くTPiCSの変更のみになっていることがたまにある | F18: 毎週行っている1か月分の危険物保管量の計算。計算自体は足し引きだが使用日とその数量を調べるのに時間がかかる | H18: 3
A19: 46071.349 | B19: 技術製造部 製造課（食品添加物） | C19: 阿部俊樹 | D19: 特にありません | E19: 配合時に指示書と照らし合わせての数量、数字の確認 | F19: 特にありません | G19: 手書きの仮伝票申請 | H19: 5 | I19: 現在使用しているAIはありません
A20: 46071.362 | B20: 技術製造部 製造課（化粧品） | C20: 松井 敬視 | D20: 特になし。 | E20: 特になし。 | F20: 特になし。 | G20: 特になし。 | H20: 3 | J20: 特になし。
A21: 46071.539 | B21: 技術製造部 製造課（食品添加物） | C21: 大川 泰弘 | D21: ファイル名：週末在庫(伊澤入力分)（会長と善鐘取締役に毎週末報告しています） | E21: 特に思い当たりません。 | F21: 現場での手順の多い配合などはこれまで改善もしてきており、今現在工程の多いものは今のところ仕方ないかなと思います。事務仕事では別にありません。 | G21: どちらかというとＰＣは苦手ですので、紙で書いているほうがかえって楽です。 | H21: 2 | I21: 使用したことがありません。 | J21: 今のところ、人員増加ができればと思います。
A22: 46071.587 | B22: 技術製造部 生産管理課 | C22: 中島 和哉 | D22: 業務内容：翌週の分までの包装指図書の進捗状況のリスト更新 理由：各包装指図書について、ひとつずつ状況を確認しているため、手間となっています。 ファイル名：包装製造指図書の進捗状況.xlsx | E22: 業務内容：包装指図書の作成(システムデータ及びExcelやpdfからのデータ転記・確認) 理由：確認する資料が複数あり、入力を間違えていても気付く仕組みができていない為 ファイル名：例 製造指図書／包装 (Rev.03) mamacharmママクリーム＜柑橘＞Amazon仕様300g.xlsx | F22: 業務内容：バルク製造量の計算用データ作成 理由：バルク製造量の計算に必要な情報(最大充填規格値、充填予定数、危険物を考慮した最大バルク製造量、開発担当者、製造予定設備等)を集めるのに時間が掛かる ファイル名：バルク製造量確認依頼(生産管理用).xlsx | G22: ありません | H22: 5 | I22: 使用AI及びAIエージェント：ChatGPT、Genspark 用途：情報収集や図解などの画像生成
A23: 46071.658 | B23: 技術製造部 製造課（化粧品） | C23: 東口智一 | D23: 生産管理システムの実績入力などのNG数や資材ロットの選択などの入力作業。 エラーの頻度が多く都度生産管理の方へ一報いれているが、エラーが出ないように 出来るのであればありがたいです。 | E23: 製造の加工賃を比較する時に、誰が作業していたかを確認するために 毎日撮影しているホワイトボードの人員割り振りの画像と各工程の加工賃を照らし合わせているので、加工賃のページで各工程と作業者がリンクしていれば捗ります。 あと、製造日を記載しといて欲しいです。 | F23: ありません。 | G23: いまのところありません。 | H23: 4 | J23: いまのところありません。
A24: 46071.788 | B24: 技術製造部 製造課（化粧品） | C24: 松下賢 | D24: 現場作業の物理的な問題になりますが、半製品置き場の収容ドラムのピッキング（有香、無香） | E24: 特にありません。 | F24: 特にありません。 | G24: 色々なチェックシート | H24: 2 | I24: ありません。
A25: 46072.424 | B25: 技術製造部 生産管理課 | C25: 島田 智章 | D25: ほぼルーティン業務はないので、特にありません。 | E25: 概算見積もりの作成、確認に多少時間はかかっています。資材メーカーの見積もりをエクセルに詳細打ち込むのと内容あっているかの確認が面倒です。 | F25: Q2と同じ。 | G25: ちょっと違うかもですが議事録関係の作成は、メモして入力するのが手間です。 音声の書き出しをしていくつもりではいます。 | H25: 1 | I25: コパイロット、チャットジーピーティー
A26: 46072.485 | B26: 管理部 管理課 | C26: 越智 | D26: 取引先からの書類を電子保存するとき、個別にアクセスしたり保存法に合わせた名前に変えるときに思います | F26: ・食添の納品書チェック 納品日・仕入先・商品名・数量・金額のリストがあればいいなと思ってます ・経費の請求書チェック 一部は請求書が届いてから発注者を探して内容確認してもらってるのでなんか良い方法ないかなとは思ってます | G26: ＰＤＦや画像をエクセルで加工できたらなと思ったことあります。 特に表などＰＤＦの変換機能やＷｏｒｄ，メモを経由してみましたが画像になってしまい加工できなかったので諦めてました そのときの環境や状況でどうしても手書きになることもあるのでそういう機能があれば教えてほしいです | H26: 5 | I26: ないです | J26: 今回の趣旨とは外れるかもしれませんがすべての現場に放送が届くようになれば良いなと思います 急ぎの電話や用件を伝えられるようにしたいです （携帯などは持込規制がありそうなので）
A27: 46072.514 | B27: 管理部 管理課 | C27: 丸中 都 | D27: ・包装工程作業日報のメール配信。 毎日ファックスで来たものをスキャンしてpdf化しているため、手間に感じることがあります。 ・無料の本での企業調査 95年版のためデータが古く、該当企業が載ってないことが多い。 | E27: 請求金額と入金額の照合。 ネットバンキングで抽出したデータを奉行クラウド内で自動照合できればミスも手間も省けるのではないかと思います。（既に方法があって、自分が知らないだけかもしれませんが） | F27: BeGardenの原価計上 （良い方法がないか現在、思案中です） | H27: 3
A28: 46072.557 | B28: 管理部 管理課 | C28: 図書 杏子 | D28: 「資材入荷状況一覧」を時々使用しますが生産管理部と管理部で共有で使用するファイルのため、どなたかが使用中ですと入力できません。入力できるタイミングをお互いに確認しあわないといけないため少し面倒だなと思います。あと使用していない時にその人が使用している表示が出ることがあります。 | E28: 「コスメファクトリー包装工程作業日報」を出荷送り状のチェックの際にロットナンバーや数量の確認に使用しています。現在コスメから本社へＦＡＸで受信し丸中さんがＰＤＦにしてメールでお送りいただいていますがときどき文字が見えにくい場合がありますのでエクセルなどになれば見やすくなり検索もできるかと思いますが、製造現場での作業の都合もあるかと思いますのでお互いに負担にならない感じで何かいい方法があればいいと思います。 | F28: 特に無いです。 | G28: 特に無いです。 | H28: 4 | I28: 使用したことがないです。

Sheet 要約
A1: ①データ管理
B2: ■ 全体的な課題
C3: 保存場所がバラバラ・ルールが曖昧
D4: 各部署・各個人で保存場所やフォルダ構成が統一されておらず、どれが最新版・正確なデータなのか分からない
D5: 古いデータの整理・削除が進まず、データが増える一方で管理負担が増大
C6: 検索性・見つけやすさの問題
D7: フォルダ階層が深い、命名ルールが曖昧などの理由で検索に時間がかかる
D8: 不要ファイルや似たようなファイルが多く、必要なデータにたどり着きにくい
C9: セキュリティ・データ損失の懸念
D10: ウイルス感染や誤操作によるデータ消失の経験があり、ローカル保存やショートカット管理への不安がある
D11: USBやメールでの持ち出しの容易さがセキュリティリスクになっている
C12: 権限管理と共有体制の不備
D13: 誰でも簡単に編集・削除できる環境であるため、誤操作が起きやすい
D14: フォルダ移動や削除に制限をかけたいという要望あり
D15: 引継ぎが不十分なまま異動・退職があると、重要データが行方不明になる
B16: ■ 部署別の主な意見
C17: 管理部
D18: フォルダ構成が乱雑で、引継ぎや検索に時間がかかる
D19: ローカル保存不可やサーバー障害への不安あり
C20: 技術製造部
D21: 保存先が複雑で、検索性が悪くルールもない
D22: 不要なデータの見極めが困難
C23: 研究開発部
D24: データ持ち出しリスク・誤操作による移動や削除への懸念あり
D25: 整理の時間がとりにくい
C26: 生産管理課
D27: フォルダ階層が深すぎる、命名・運用ルールが未整備
D28: ショートカットの消失経験あり
C29: 直販事業部
D30: 個人管理でバラバラ、最新ファイルの判別が困難
D31: システムでの一元管理が理想
C32: 品質保証部
D33: 旧社名・旧データが混在して検索困難
D34: フォルダ構成が無秩序、部署専用フォルダが必要
D35: 重要データの持ち出しリスクや未使用ファイルの放置が課題
C36: 企画課
D37: 管理方法に対する理解が浅く、バックアップの有無も不明
D38: 過去のデータ消失事例に対する不安あり
B39: ■ まとめ
C40: 各部署共通の課題として「保存場所の統一」「フォルダ構成と命名のルール化」「不要データの整理」
...

Sheet 集計P
A1: 0無回答・無関心 1気になる 2前向き
A3: ①データ管理 | B3: 部署名 | C3: データの個数 / ①データ管理 | E3: ②仕組み・ルール | F3: 部署名 | G3: データの個数 / ②仕組み・ルール | I3: ③MS365 | J3: 部署名 | K3: データの個数 / ③MS365 | M3: ④セキュリティ | N3: 部署名 | O3: データの個数 / ④セキュリティ | Q3: ⑤ITスキル向上 | R3: 部署名 | S3: データの個数 / ⑤ITスキル向上 | U3: ⑥その他 | V3: 部署名 | W3: データの個数 / ⑥その他
A4: 2 | B4: 管理部 | C4: 3 | E4: 2 | F4: 管理部 | G4: 2 | I4: 2 | J4: 営業課 | K4: 1 | M4: 2 | N4: 営業課 | O4: 1 | Q4: 2 | R4: 営業課 | S4: 2 | U4: 2 | V4: 営業課 | W4: 2
B5: 技術製造部 | C5: 6 | F5: 企画課 | G5: 1 | J5: 管理部 | K5: 3 | N5: 管理部 | O5: 2 | R5: 管理部 | S5: 2 | V5: 管理部 | W5: 2
B6: 研究開発部 | C6: 3 | F6: 技術製造部 | G6: 6 | J6: 企画課 | K6: 1 | N6: 企画課 | O6: 2 | R6: 企画課 | S6: 1 | V6: 技術製造部 | W6: 1
B7: 生産管理課 | C7: 5 | F7: 研究開発部 | G7: 3 | J7: 技術製造部 | K7: 2 | N7: 技術製造部 | O7: 1 | R7: 技術製造部 | S7: 7 | V7: 研究開発部 | W7: 1
B8: 直販事業部 | C8: 2 | F8: 生産管理課 | G8: 7 | J8: 研究開発部 | K8: 2 | N8: 研究開発部 | O8: 4 | R8: 研究開発部 | S8: 2 | V8: 生産管理課 | W8: 3
B9: 品質保証部 | C9: 5 | F9: 直販事業部 | G9: 1 | J9: 生産管理課 | K9: 4 | N9: 生産管理課 | O9: 5 | R9: 生産管理課 | S9: 7 | V9: 直販事業部 | W9: 1
A10: 2 集計 | C10: 24 | D10: =C10/45 -> 0.53333333 | F10: 品質保証部 | G10: 3 | J10: 直販事業部 | K10: 2 | N10: 直販事業部 | O10: 2 | R10: 直販事業部 | S10: 1 | V10: 品質保証部 | W10: 1
A11: 1 | B11: 企画課 | C11: 2 | E11: 2 集計 | G11: 23 | H11: =G11/45 -> 0.51111111 | J11: 品質保証部 | K11: 1 | N11: 品質保証部 | O11: 1 | R11: 品質保証部 | S11: 4 | U11: 2 集計 | W11: 11 | X11: =W11/45 -> 0.24444444
B12: 技術製造部 | C12: 4 | E12: 1 | F12: 企画課 | G12: 1 | I12: 2 集計 | K12: 16 | L12: =K12/45 -> 0.35555556 | M12: 2 集計 | O12: 18 | P12: =O12/45 -> 0.4 | Q12: 2 集計 | S12: 26 | T12: =S12/45 -> 0.57777778 | U12: 1 | V12: 技術製造部 | W12: 8
B13: 研究開発部 | C13: 2 | F13: 技術製造部 | G13: 3 | I13: 1 | J13: 企画課 | K13: 1 | M13: 1 | N13: 管理部 | O13: 1 | Q13: 1 | R13: 管理部 | S13: 1 | V13: 研究開発部 | W13: 2
B14: 生産管理課 | C14: 1 | F14: 研究開発部 | G14: 1 | J14: 技術製造部 | K14: 6 | M14: 1 集計 | O14: 1 | P14: =O14/45 -> 0.022222222 | R14: 企画課 | S14: 1 | V14: 生産管理課 | W14: 2
A15: 1 集計 | C15: 9 | D15: =C15/45 -> 0.2 | F15: 直販事業部 | G15: 1 | J15: 研究開発部 | K15: 2 | M15: 0 | N15: 営業課 | O15: 3 | R15: 技術製造部 | S15: 3 | U15: 1 集計 | W15: 12 | X15: =W15/45 -> 0.26666667
A16: 0 | B16: 営業課 | C16: 4 | E16: 1 集計 | G16: 6 | H16: =G16/45 -> 0.13333333 | J16: 生産管理課 | K16: 3 | N16: 技術製造部 | O16: 13 | R16: 研究開発部 | S16: 3 | U16: 0 | V16: 営業課 | W16: 2
B17: 技術製造部 | C17: 4 | E17: 0 | F17: 営業課 | G17: 4 | I17: 1 集計 | K17: 12 | L17: =K17/45 -> 0.26666667 | N17: 研究開発部 | O17: 2 | R17: 生産管理課 | S17: 1 | V17: 管理部 | W17: 1
B18: 研究開発部 | C18: 1 | F18: 管理部 | G18: 1 | I18: 0 | J18: 営業課 | K18: 3 | N18: 生産管理課 | O18: 3 | R18: 直販事業部 | S18: 1 | V18: 企画課 | W18: 2
